Workbook
Name R.BASECURVE: Australia!$J$25:$J$174
Name R.BASECURVE: Canada!$J$25:$J$174
Name R.BASECURVE: China!$J$25:$J$174
Name R.BASECURVE: Colombia!$J$25:$J$174
Name R.BASECURVE: Czechia!$J$25:$J$174
Name R.BASECURVE: Denmark!$J$25:$J$174
Name R.BASECURVE: 'Hong Kong'!$J$25:$J$174
Name R.BASECURVE: Hungary!$J$25:$J$174
Name R.BASECURVE: Iceland!$J$25:$J$174
Name R.BASECURVE: Japan!$J$25:$J$174
Name R.BASECURVE: Norway!$J$25:$J$174
Name R.BASECURVE: Poland!$J$25:$J$174
Name R.BASECURVE: Romania!$J$25:$J$174
Name R.BASECURVE: Sweden!$J$25:$J$174
Name R.BASECURVE: Switzerland!$J$25:$J$174
Name R.BASECURVE: Taiwan!$J$25:$J$174
Name R.BASECURVE: UK!$J$25:$J$174
Name R.BASECURVE: US!$J$25:$J$174
Name R.BASECURVE: EUR!$J$25:$J$174
Name R.BOOTSTRAPPED_CURVE: Australia!$K$25:$K$174
Name R.BOOTSTRAPPED_CURVE: Canada!$K$25:$K$174
Name R.BOOTSTRAPPED_CURVE: China!$K$25:$K$174
Name R.BOOTSTRAPPED_CURVE: Colombia!$K$25:$K$174
Name R.BOOTSTRAPPED_CURVE: Czechia!$K$25:$K$174
Name R.BOOTSTRAPPED_CURVE: Denmark!$K$25:$K$174
Name R.BOOTSTRAPPED_CURVE: 'Hong Kong'!$K$25:$K$174
Name R.BOOTSTRAPPED_CURVE: Hungary!$K$25:$K$174
Name R.BOOTSTRAPPED_CURVE: Iceland!$K$25:$K$174
Name R.BOOTSTRAPPED_CURVE: Japan!$K$25:$K$174
Name R.BOOTSTRAPPED_CURVE: Norway!$K$25:$K$174
Name R.BOOTSTRAPPED_CURVE: Poland!$K$25:$K$174
Name R.BOOTSTRAPPED_CURVE: Romania!$K$25:$K$174
Name R.BOOTSTRAPPED_CURVE: Sweden!$K$25:$K$174
Name R.BOOTSTRAPPED_CURVE: Switzerland!$K$25:$K$174
Name R.BOOTSTRAPPED_CURVE: Taiwan!$K$25:$K$174
Name R.BOOTSTRAPPED_CURVE: UK!$K$25:$K$174
Name R.BOOTSTRAPPED_CURVE: US!$K$25:$K$174
Name R.BOOTSTRAPPED_CURVE: EUR!$K$25:$K$174
Name R.DLT: Australia!$H$25:$H$174
Name R.DLT: Canada!$H$25:$H$174
Name R.DLT: China!$H$25:$H$174
Name R.DLT: Colombia!$H$25:$H$174
Name R.DLT: Czechia!$H$25:$H$174
Name R.DLT: Denmark!$H$25:$H$174
Name R.DLT: 'Hong Kong'!$H$25:$H$174
Name R.DLT: Hungary!$H$25:$H$174
Name R.DLT: Iceland!$H$25:$H$174
Name R.DLT: Japan!$H$25:$H$174
Name R.DLT: Norway!$H$25:$H$174
Name R.DLT: Poland!$H$25:$H$174
Name R.DLT: Romania!$H$25:$H$174
Name R.DLT: Sweden!$H$25:$H$174
Name R.DLT: Switzerland!$H$25:$H$174
Name R.DLT: Taiwan!$H$25:$H$174
Name R.DLT: UK!$H$25:$H$174
Name R.DLT: US!$H$25:$H$174
Name R.DLT: EUR!$H$25:$H$174
Name R.MATURITY: Australia!$G$25:$G$174
Name R.MATURITY: Canada!$G$25:$G$174
Name R.MATURITY: China!$G$25:$G$174

Sheet Summary
B1: Max error | C1: Max error times 10.000 | E1: Max error first 50 years | F1: Max error first 50 years times 10.000
A2: Colombia | B2: =Colombia!$O$1 -> 0.00227 | C2: =B2*10000 -> 22.7 | E2: =Colombia!$P$1 -> 0.00227 | F2: =E2*10000 -> 22.7
A3: China | B3: =China!$O$1 -> 0.00167 | C3: =B3*10000 -> 16.7 | E3: =China!$P$1 -> 0.00167 | F3: =E3*10000 -> 16.7
A4: Iceland | B4: =Iceland!$O$1 -> 0.00124 | C4: =B4*10000 -> 12.4 | E4: =Iceland!$P$1 -> 0.00124 | F4: =E4*10000 -> 12.4
A5: Norway | B5: =Norway!$O$1 -> 0.00073 | C5: =B5*10000 -> 7.3 | E5: =Norway!$P$1 -> 0.00073 | F5: =E5*10000 -> 7.3
A6: Canada | B6: =Canada!$O$1 -> 0.00049 | C6: =B6*10000 -> 4.9 | E6: =Canada!$P$1 -> 0.00049 | F6: =E6*10000 -> 4.9
A7: Poland | B7: =Poland!$O$1 -> 0.0004 | C7: =B7*10000 -> 4 | E7: =Poland!$P$1 -> 0.0004 | F7: =E7*10000 -> 4
A8: Japan | B8: =Japan!O1 -> 0.00043 | C8: =B8*10000 -> 4.3 | E8: =Japan!$P$1 -> 0.00043 | F8: =E8*10000 -> 4.3
A9: Czechia | B9: =Czechia!$O$1 -> 0.00039 | C9: =B9*10000 -> 3.9 | E9: =Czechia!$P$1 -> 0.00039 | F9: =E9*10000 -> 3.9
A10: United Kingdom | B10: =UK!$O$1 -> 0.0004 | C10: =B10*10000 -> 4 | E10: =UK!$P$1 -> 0.0004 | F10: =E10*10000 -> 4
A11: Australia | B11: =Australia!$O$1 -> 0.00043 | C11: =B11*10000 -> 4.3 | E11: =Australia!$P$1 -> 0.00043 | F11: =E11*10000 -> 4.3
A12: US | B12: =US!O1 -> 0.00034 | C12: =B12*10000 -> 3.4 | E12: =US!$P$1 -> 0.00034 | F12: =E12*10000 -> 3.4
A13: Taiwan | B13: =Taiwan!O1 -> 0.00013 | C13: =B13*10000 -> 1.3 | E13: =Taiwan!$P$1 -> 0.00013 | F13: =E13*10000 -> 1.3
A14: Sweden | B14: =Sweden!$O$1 -> 0.00012 | C14: =B14*10000 -> 1.2 | E14: =Sweden!$P$1 -> 0.00012 | F14: =E14*10000 -> 1.2
A15: Romania | B15: =Romania!$O$1 -> 0.00019 | C15: =B15*10000 -> 1.9 | E15: =Romania!$P$1 -> 0.00019 | F15: =E15*10000 -> 1.9
A16: Hungary | B16: =Hungary!$O$1 -> 0.0002 | C16: =B16*10000 -> 2 | E16: =Hungary!$P$1 -> 0.0002 | F16: =E16*10000 -> 2
A17: Denmark | B17: =Denmark!O1 -> 0.00017 | C17: =B17*10000 -> 1.7 | E17: =Denmark!$P$1 -> 0.00017 | F17: =E17*10000 -> 1.7
A18: Hong Kong | B18: ='Hong Kong'!$O$1 -> 0.00028 | C18: =B18*10000 -> 2.8 | E18: ='Hong Kong'!$P$1 -> 0.00028 | F18: =E18*10000 -> 2.8
A19: Switzerland | B19: =Switzerland!$O$1 -> 0.00031 | C19: =B19*10000 -> 3.1 | E19: =Switzerland!$P$1 -> 0.00031 | F19: =E19*10000 -> 3.1
A20: Euro | B20: =EUR!$O$1 -> 0.00016 | C20: =B20*10000 -> 1.6 | E20: =EUR!$P$1 -> 0.00016 | F20: =E20*10000 -> 1.6

Sheet Colombia
A1: Bootstrapped Zero Rate CC | B1: Extrapolated Zero Rate AC / Basic RFR | C1: Bootstrapped Zero Rate CC | D1: Basic RFR | F1: =SUM(F2:F151) -> 4.4964032e-15 | G1: =SUM(G2:G151) -> 0 | K1: Maturity | L1: Smith-Wilson | M1: Constant forward | O1: =MAX(O2:O151) -> 0.00227 | P1: =MAX(O2:O51) -> 0.00227
A2: 0.11394457 | B2: 0.12069 | C2: 0.11394457 | D2: 0.12069 | F2: =IF(C2<>"",A2-C2,"") -> 9.7144515e-17 | G2: =B2-D2 -> 0 | K2: 1 | L2: 0.12069 | M2: =D2 -> 0.12069 | O2: =MAX(ABS(L2-M2)) -> 0
A3: 0.11648442 | B3: 0.12354 | C3: 0.11648442 | D3: 0.12354 | F3: =IF(C3<>"",A3-C3,"") -> 3.3306691e-16 | G3: =B3-D3 -> 0 | K3: 2 | L3: 0.12354 | M3: =D3 -> 0.12354 | O3: =MAX(ABS(L3-M3)) -> 0
A4: 0.11777415 | B4: 0.12499 | C4: 0.11777415 | D4: 0.12499 | F4: =IF(C4<>"",A4-C4,"") -> 9.7144515e-17 | G4: =B4-D4 -> 0 | K4: 3 | L4: 0.12499 | M4: =D4 -> 0.12499 | O4: =MAX(ABS(L4-M4)) -> 0
A5: 0.11851166 | B5: 0.12582 | C5: 0.11851166 | D5: 0.12582 | F5: =IF(C5<>"",A5-C5,"") -> 8.3266727e-16 | G5: =B5-D5 -> 0 | K5: 4 | L5: 0.12582 | M5: =D5 -> 0.12582 | O5: =MAX(ABS(L5-M5)) -> 0
A6: 0.11865377 | B6: 0.12598 | C6: 0.11865377 | D6: 0.12598 | F6: =IF(C6<>"",A6-C6,"") -> 8.3266727e-16 | G6: =B6-D6 -> 0 | K6: 5 | L6: 0.12598 | M6: =D6 -> 0.12598 | O6: =MAX(ABS(L6-M6)) -> 0
A7: 0.11862712 | B7: 0.12595 | C7: 0.11862712 | D7: 0.12595 | F7: =IF(C7<>"",A7-C7,"") -> 6.5225603e-16 | G7: =B7-D7 -> 0 | K7: 6 | L7: 0.12595 | M7: =D7 -> 0.12595 | O7: =MAX(ABS(L7-M7)) -> 0
A8: 0.11852942 | B8: 0.12584 | C8: 0.11852942 | D8: 0.12584 | F8: =IF(C8<>"",A8-C8,"") -> 2.0816682e-16 | G8: =B8-D8 -> 0 | K8: 7 | L8: 0.12584 | M8: =D8 -> 0.12584 | O8: =MAX(ABS(L8-M8)) -> 0
A9: 0.11836953 | B9: 0.12566 | C9: 0.11836953 | D9: 0.12566 | F9: =IF(C9<>"",A9-C9,"") -> 4.1633363e-16 | G9: =B9-D9 -> 0 | K9: 8 | L9: 0.12566 | M9: =D9 -> 0.12566 | O9: =MAX(ABS(L9-M9)) -> 0
A10: 0.11824515 | B10: 0.12552 | C10: 0.11824515 | D10: 0.12552 | F10: =IF(C10<>"",A10-C10,"") -> 8.3266727e-16 | G10: =B10-D10 -> 0 | K10: 9 | L10: 0.12552 | M10: =D10 -> 0.12552 | O10: =MAX(ABS(L10-M10)) -> 0
A11: 0.11826292 | B11: 0.12554 | C11: 0.11826292 | D11: 0.12554 | F11: =IF(C11<>"",A11-C11,"") -> 1.9428903e-16 | G11: =B11-D11 -> 0 | K11: 10 | L11: 0.12554 | M11: =D11 -> 0.12554 | O11: =MAX(ABS(L11-M11)) -> 0
A12: #N/A | B12: 0.12514 | D12: 0.12514 | F12: =IF(C12<>"",A12-C12,"") | G12: =B12-D12 -> 0 | K12: 11 | L12: 0.12517 | M12: =D12 -> 0.12514 | O12: =MAX(ABS(L12-M12)) -> 3e-05
A13: #N/A | B13: 0.12409 | D13: 0.12409 | F13: =IF(C13<>"",A13-C13,"") | G13: =B13-D13 -> 0 | K13: 12 | L13: 0.12435 | M13: =D13 -> 0.12409 | O13: =MAX(ABS(L13-M13)) -> 0.00026
A14: #N/A | B14: 0.12261 | D14: 0.12261 | F14: =IF(C14<>"",A14-C14,"") | G14: =B14-D14 -> 0 | K14: 13 | L14: 0.12319 | M14: =D14 -> 0.12261 | O14: =MAX(ABS(L14-M14)) -> 0.00058
A15: #N/A | B15: 0.12085 | D15: 0.12085 | F15: =IF(C15<>"",A15-C15,"") | G15: =B15-D15 -> 0 | K15: 14 | L15: 0.12178 | M15: =D15 -> 0.12085 | O15: =MAX(ABS(L15-M15)) -> 0.00093
A16: #N/A | B16: 0.11893 | D16: 0.11893 | F16: =IF(C16<>"",A16-C16,"") | G16: =B16-D16 -> 0 | K16: 15 | L16: 0.12018 | M16: =D16 -> 0.11893 | O16: =MAX(ABS(L16-M16)) -> 0.00125
A17: #N/A | B17: 0.1169 | D17: 0.1169 | F17: =IF(C17<>"",A17-C17,"") | G17: =B17-D17 -> 0 | K17: 16 | L17: 0.11844 | M17: =D17 -> 0.1169 | O17: =MAX(ABS(L17-M17)) -> 0.00154
A18: #N/A | B18: 0.11483 | D18: 0.11483 | F18: =IF(C18<>"",A18-C18,"") | G18: =B18-D18 -> 0 | K18: 17 | L18: 0.11661 | M18: =D18 -> 0.11483 | O18: =MAX(ABS(L18-M18)) -> 0.00178
A19: #N/A | B19: 0.11274 | D19: 0.11274 | F19: =IF(C19<>"",A19-C19,"") | G19: =B19-D19 -> 0 | K19: 18 | L19: 0.11472 | M19: =D19 -> 0.11274 | O19: =MAX(ABS(L19-M19)) -> 0.00198
A20: #N/A | B20: 0.11068 | D20: 0.11068 | F20: =IF(C20<>"",A20-C20,"") | G20: =B20-D20 -> 0 | K20: 19 | L20: 0.11279 | M20: =D20 -> 0.11068 | O20: =MAX(ABS(L20-M20)) -> 0.00211
A21: #N/A | B21: 0.10864 | D21: 0.10864 | F21: =IF(C21<>"",A21-C21,"") | G21: =B21-D21 -> 0 | K21: 20 | L21: 0.11085 | M21: =D21 -> 0.10864 | O21: =MAX(ABS(L21-M21)) -> 0.00221
A22: #N/A | B22: 0.10666 | D22: 0.10666 | F22: =IF(C22<>"",A22-C22,"") | G22: =B22-D22 -> 0 | K22: 21 | L22: 0.10891 | M22: =D22 -> 0.10666 | O22: =MAX(ABS(L22-M22)) -> 0.00225
A23: #N/A | B23: 0.10473 | D23: 0.10473 | F23: =IF(C23<>"",A23-C23,"") | G23: =B23-D23 -> 0 | K23: 22 | L23: 0.107 | M23: =D23 -> 0.10473 | O23: =MAX(ABS(L23-M23)) -> 0.00227
... A151: #N/A | B151: 0.05229 | D151: 0.05229 | F151: =IF(C151<>"",A151-C151,"") | G151: =B151-D151 -> 0 | K151: 150 | L151: 0.05247 | M151: =D151 -> 0.05229 | O151: =MAX(ABS(L151-M151)) -> 0.00018

Sheet China
A1: Bootstrapped Zero Rate CC | B1: Extrapolated Zero Rate AC / Basic RFR | C1: Bootstrapped Zero Rate CC | D1: Basic RFR | F1: =SUM(F2:F151) -> 4.0245585e-16 | G1: =SUM(G2:G151) -> 0 | K1: Maturity | L1: Smith-Wilson | M1: Constant forward | O1: =MAX(O2:O151) -> 0.00167 | P1: =MAX(O2:O51) -> 0.00167
A2: 0.011286072 | B2: 0.01135 | C2: 0.011286072 | D2: 0.01135 | F2: =IF(C2<>"",A2-C2,"") -> 9.0205621e-17 | G2: =B2-D2 -> 0 | K2: 1 | L2: 0.01135 | M2: =D2 -> 0.01135 | O2: =MAX(ABS(L2-M2)) -> 0
A3: 0.011286072 | B3: 0.01135 | C3: 0.011286072 | D3: 0.01135 | F3: =IF(C3<>"",A3-C3,"") -> 2.4286129e-17 | G3: =B3-D3 -> 0 | K3: 2 | L3: 0.01135 | M3: =D3 -> 0.01135 | O3: =MAX(ABS(L3-M3)) -> 0
A4: 0.011483808 | B4: 0.01155 | C4: 0.011483808 | D4: 0.01155 | F4: =IF(C4<>"",A4-C4,"") -> 1.9081958e-17 | G4: =B4-D4 -> 0 | K4: 3 | L4: 0.01155 | M4: =D4 -> 0.01155 | O4: =MAX(ABS(L4-M4)) -> 0
A5: 0.011790221 | B5: 0.01186 | C5: 0.011790221 | D5: 0.01186 | F5: =IF(C5<>"",A5-C5,"") -> 1.2143064e-17 | G5: =B5-D5 -> 0 | K5: 4 | L5: 0.01186 | M5: =D5 -> 0.01186 | O5: =MAX(ABS(L5-M5)) -> 0
A6: 0.012096541 | B6: 0.01217 | C6: 0.012096541 | D6: 0.01217 | F6: =IF(C6<>"",A6-C6,"") -> 4.8572257e-17 | G6: =B6-D6 -> 0 | K6: 5 | L6: 0.01217 | M6: =D6 -> 0.01217 | O6: =MAX(ABS(L6-M6)) -> 0
A7: 0.012442153 | B7: 0.01252 | C7: 0.012442153 | D7: 0.01252 | F7: =IF(C7<>"",A7-C7,"") -> 8.3266727e-17 | G7: =B7-D7 -> 0 | K7: 6 | L7: 0.01228 | M7: =D7 -> 0.01252 | O7: =MAX(ABS(L7-M7)) -> 0.00024
A8: 0.012689019 | B8: 0.01277 | C8: 0.012689019 | D8: 0.01277 | F8: =IF(C8<>"",A8-C8,"") -> 0 | G8: =B8-D8 -> 0 | K8: 7 | L8: 0.01234 | M8: =D8 -> 0.01277 | O8: =MAX(ABS(L8-M8)) -> 0.00043
A9: 0.012874169 | B9: 0.01296 | C9: 0.012874169 | D9: 0.01296 | F9: =IF(C9<>"",A9-C9,"") -> 1.2143064e-17 | G9: =B9-D9 -> 0 | K9: 8 | L9: 0.01248 | M9: =D9 -> 0.01296 | O9: =MAX(ABS(L9-M9)) -> 0.00048
A10: 0.013018174 | B10: 0.0131 | C10: 0.013018174 | D10: 0.0131 | F10: =IF(C10<>"",A10-C10,"") -> 5.3776428e-17 | G10: =B10-D10 -> 0 | K10: 9 | L10: 0.01277 | M10: =D10 -> 0.0131 | O10: =MAX(ABS(L10-M10)) -> 0.00033
A11: 0.013133378 | B11: 0.01322 | C11: 0.013133378 | D11: 0.01322 | F11: =IF(C11<>"",A11-C11,"") -> 5.8980598e-17 | G11: =B11-D11 -> 0 | K11: 10 | L11: 0.01322 | M11: =D11 -> 0.01322 | O11: =MAX(ABS(L11-M11)) -> 0
A12: #N/A | B12: 0.01345 | D12: 0.01345 | F12: =IF(C12<>"",A12-C12,"") | G12: =B12-D12 -> 0 | K12: 11 | L12: 0.01384 | M12: =D12 -> 0.01345 | O12: =MAX(ABS(L12-M12)) -> 0.00039
A13: #N/A | B13: 0.01386 | D13: 0.01386 | F13: =IF(C13<>"",A13-C13,"") | G13: =B13-D13 -> 0 | K13: 12 | L13: 0.01457 | M13: =D13 -> 0.01386 | O13: =MAX(ABS(L13-M13)) -> 0.00071
A14: #N/A | B14: 0.0144 | D14: 0.0144 | F14: =IF(C14<>"",A14-C14,"") | G14: =B14-D14 -> 0 | K14: 13 | L14: 0.01536 | M14: =D14 -> 0.0144 | O14: =MAX(ABS(L14-M14)) -> 0.00096
A15: #N/A | B15: 0.01501 | D15: 0.01501 | F15: =IF(C15<>"",A15-C15,"") | G15: =B15-D15 -> 0 | K15: 14 | L15: 0.01617 | M15: =D15 -> 0.01501 | O15: =MAX(ABS(L15-M15)) -> 0.00116
A16: #N/A | B16: 0.01568 | D16: 0.01568 | F16: =IF(C16<>"",A16-C16,"") | G16: =B16-D16 -> 0 | K16: 15 | L16: 0.01699 | M16: =D16 -> 0.01568 | O16: =MAX(ABS(L16-M16)) -> 0.00131
A17: #N/A | B17: 0.01636 | D17: 0.01636 | F17: =IF(C17<>"",A17-C17,"") | G17: =B17-D17 -> 0 | K17: 16 | L17: 0.01779 | M17: =D17 -> 0.01636 | O17: =MAX(ABS(L17-M17)) -> 0.00143
A18: #N/A | B18: 0.01707 | D18: 0.01707 | F18: =IF(C18<>"",A18-C18,"") | G18: =B18-D18 -> 0 | K18: 17 | L18: 0.01858 | M18: =D18 -> 0.01707 | O18: =MAX(ABS(L18-M18)) -> 0.00151
A19: #N/A | B19: 0.01777 | D19: 0.01777 | F19: =IF(C19<>"",A19-C19,"") | G19: =B19-D19 -> 0 | K19: 18 | L19: 0.01934 | M19: =D19 -> 0.01777 | O19: =MAX(ABS(L19-M19)) -> 0.00157
A20: #N/A | B20: 0.01846 | D20: 0.01846 | F20: =IF(C20<>"",A20-C20,"") | G20: =B20-D20 -> 0 | K20: 19 | L20: 0.02008 | M20: =D20 -> 0.01846 | O20: =MAX(ABS(L20-M20)) -> 0.00162
A21: #N/A | B21: 0.01914 | D21: 0.01914 | F21: =IF(C21<>"",A21-C21,"") | G21: =B21-D21 -> 0 | K21: 20 | L21: 0.02079 | M21: =D21 -> 0.01914 | O21: =MAX(ABS(L21-M21)) -> 0.00165
A22: #N/A | B22: 0.0198 | D22: 0.0198 | F22: =IF(C22<>"",A22-C22,"") | G22: =B22-D22 -> 0 | K22: 21 | L22: 0.02147 | M22: =D22 -> 0.0198 | O22: =MAX(ABS(L22-M22)) -> 0.00167
A23: #N/A | B23: 0.02045 | D23: 0.02045 | F23: =IF(C23<>"",A23-C23,"") | G23: =B23-D23 -> 0 | K23: 22 | L23: 0.02212 | M23: =D23 -> 0.02045 | O23: =MAX(ABS(L23-M23)) -> 0.00167
... A151: #N/A | B151: 0.03836 | D151: 0.03836 | F151: =IF(C151<>"",A151-C151,"") | G151: =B151-D151 -> 0 | K151: 150 | L151: 0.0387 | M151: =D151 -> 0.03836 | O151: =MAX(ABS(L151-M151)) -> 0.00034

Sheet Iceland
A1: Bootstrapped Zero Rate CC | B1: Extrapolated Zero Rate AC / Basic RFR | C1: Bootstrapped Zero Rate CC | D1: Basic RFR | F1: =SUM(F2:F151) -> 3.1918912e-16 | G1: =SUM(G2:G151) -> 0 | K1: Maturity | L1: Smith-Wilson | M1: Constant forward | O1: =MAX(O2:O151) -> 0.00124 | P1: =MAX(O2:O51) -> 0.00124
A2: 0.078774211 | B2: 0.08196 | C2: 0.078774211 | D2: 0.08196 | F2: =IF(C2<>"",A2-C2,"") -> 4.1633363e-17 | G2: =B2-D2 -> 0 | K2: 1 | L2: 0.08196 | M2: =D2 -> 0.08196 | O2: =MAX(ABS(L2-M2)) -> 0
A3: 0.075091295 | B3: 0.07798 | C3: 0.075091295 | D3: 0.07798 | F3: =IF(C3<>"",A3-C3,"") -> 6.9388939e-17 | G3: =B3-D3 -> 0 | K3: 2 | L3: 0.07922 | M3: =D3 -> 0.07798 | O3: =MAX(ABS(L3-M3)) -> 0.00124
A4: 0.073863657 | B4: 0.07666 | C4: 0.073863657 | D4: 0.07666 | F4: =IF(C4<>"",A4-C4,"") -> 5.5511151e-17 | G4: =B4-D4 -> 0 | K4: 3 | L4: 0.07666 | M4: =D4 -> 0.07666 | O4: =MAX(ABS(L4-M4)) -> 0
A5: 0.071892661 | B5: 0.07454 | C5: 0.071892661 | D5: 0.07454 | F5: =IF(C5<>"",A5-C5,"") -> 0 | G5: =B5-D5 -> 0 | K5: 4 | L5: 0.07478 | M5: =D5 -> 0.07454 | O5: =MAX(ABS(L5-M5)) -> 0.00024
A6: 0.070710063 | B6: 0.07327 | C6: 0.070710063 | D6: 0.07327 | F6: =IF(C6<>"",A6-C6,"") -> 1.3877788e-17 | G6: =B6-D6 -> 0 | K6: 5 | L6: 0.07327 | M6: =D6 -> 0.07327 | O6: =MAX(ABS(L6-M6)) -> 0
A7: 0.068990575 | B7: 0.07143 | C7: 0.068990575 | D7: 0.07143 | F7: =IF(C7<>"",A7-C7,"") -> 1.3877788e-17 | G7: =B7-D7 -> 0 | K7: 6 | L7: 0.07194 | M7: =D7 -> 0.07143 | O7: =MAX(ABS(L7-M7)) -> 0.00051
A8: 0.06776237 | B8: 0.07011 | C8: 0.06776237 | D8: 0.07011 | F8: =IF(C8<>"",A8-C8,"") -> 2.7755576e-17 | G8: =B8-D8 -> 0 | K8: 7 | L8: 0.0707 | M8: =D8 -> 0.07011 | O8: =MAX(ABS(L8-M8)) -> 0.00059
A9: 0.066841216 | B9: 0.06913 | C9: 0.066841216 | D9: 0.06913 | F9: =IF(C9<>"",A9-C9,"") -> 6.9388939e-17 | G9: =B9-D9 -> 0 | K9: 8 | L9: 0.06952 | M9: =D9 -> 0.06913 | O9: =MAX(ABS(L9-M9)) -> 0.00039
A10: 0.066124762 | B10: 0.06836 | C10: 0.066124762 | D10: 0.06836 | F10: =IF(C10<>"",A10-C10,"") -> 2.7755576e-17 | G10: =B10-D10 -> 0 | K10: 9 | L10: 0.06836 | M10: =D10 -> 0.06836 | O10: =MAX(ABS(L10-M10)) -> 0
A11: #N/A | B11: 0.06759 | D11: 0.06759 | F11: =IF(C11<>"",A11-C11,"") | G11: =B11-D11 -> 0 | K11: 10 | L11: 0.06721 | M11: =D11 -> 0.06759 | O11: =MAX(ABS(L11-M11)) -> 0.00038
A12: #N/A | B12: 0.06669 | D12: 0.06669 | F12: =IF(C12<>"",A12-C12,"") | G12: =B12-D12 -> 0 | K12: 11 | L12: 0.06608 | M12: =D12 -> 0.06669 | O12: =MAX(ABS(L12-M12)) -> 0.00061
A13: #N/A | B13: 0.06573 | D13: 0.06573 | F13: =IF(C13<>"",A13-C13,"") | G13: =B13-D13 -> 0 | K13: 12 | L13: 0.06498 | M13: =D13 -> 0.06573 | O13: =MAX(ABS(L13-M13)) -> 0.00075
A14: #N/A | B14: 0.06473 | D14: 0.06473 | F14: =IF(C14<>"",A14-C14,"") | G14: =B14-D14 -> 0 | K14: 13 | L14: 0.06391 | M14: =D14 -> 0.06473 | O14: =MAX(ABS(L14-M14)) -> 0.00082
A15: #N/A | B15: 0.06372 | D15: 0.06372 | F15: =IF(C15<>"",A15-C15,"") | G15: =B15-D15 -> 0 | K15: 14 | L15: 0.06287 | M15: =D15 -> 0.06372 | O15: =MAX(ABS(L15-M15)) -> 0.00085
A16: #N/A | B16: 0.06273 | D16: 0.06273 | F16: =IF(C16<>"",A16-C16,"") | G16: =B16-D16 -> 0 | K16: 15 | L16: 0.06187 | M16: =D16 -> 0.06273 | O16: =MAX(ABS(L16-M16)) -> 0.00086
A17: #N/A | B17: 0.06175 | D17: 0.06175 | F17: =IF(C17<>"",A17-C17,"") | G17: =B17-D17 -> 0 | K17: 16 | L17: 0.0609 | M17: =D17 -> 0.06175 | O17: =MAX(ABS(L17-M17)) -> 0.00085
A18: #N/A | B18: 0.0608 | D18: 0.0608 | F18: =IF(C18<>"",A18-C18,"") | G18: =B18-D18 -> 0 | K18: 17 | L18: 0.05997 | M18: =D18 -> 0.0608 | O18: =MAX(ABS(L18-M18)) -> 0.00083
A19: #N/A | B19: 0.05988 | D19: 0.05988 | F19: =IF(C19<>"",A19-C19,"") | G19: =B19-D19 -> 0 | K19: 18 | L19: 0.05908 | M19: =D19 -> 0.05988 | O19: =MAX(ABS(L19-M19)) -> 0.0008
A20: #N/A | B20: 0.059 | D20: 0.059 | F20: =IF(C20<>"",A20-C20,"") | G20: =B20-D20 -> 0 | K20: 19 | L20: 0.05823 | M20: =D20 -> 0.059 | O20: =MAX(ABS(L20-M20)) -> 0.00077
A21: #N/A | B21: 0.05815 | D21: 0.05815 | F21: =IF(C21<>"",A21-C21,"") | G21: =B21-D21 -> 0 | K21: 20 | L21: 0.05741 | M21: =D21 -> 0.05815 | O21: =MAX(ABS(L21-M21)) -> 0.00074
A22: #N/A | B22: 0.05733 | D22: 0.05733 | F22: =IF(C22<>"",A22-C22,"") | G22: =B22-D22 -> 0 | K22: 21 | L22: 0.05662 | M22: =D22 -> 0.05733 | O22: =MAX(ABS(L22-M22)) -> 0.00071
... A151: #N/A | B151: 0.03684 | D151: 0.03684 | F151: =IF(C151<>"",A151-C151,"") | G151: =B151-D151 -> 0 | K151: 150 | L151: 0.03675 | M151: =D151 -> 0.03684 | O151: =MAX(ABS(L151-M151)) -> 9e-05

Sheet Norway
A1: Bootstrapped Zero Rate CC | B1: Extrapolated Zero Rate AC / Basic RFR | C1: Bootstrapped Zero Rate CC | D1: Basic RFR | F1: =SUM(F2:F151) -> 5.2735594e-16 | G1: =SUM(G2:G151) -> 0 | K1: Maturity | L1: Smith-Wilson | M1: Constant forward | O1: =MAX(O2:O151) -> 0.00073 | P1: =MAX(O2:O51) -> 0.00073
A2: 0.049884803 | B2: 0.05115 | C2: 0.049884803 | D2: 0.05115 | F2: =IF(C2<>"",A2-C2,"") -> 5.5511151e-17 | G2: =B2-D2 -> 0 | K2: 1 | L2: 0.05188 | M2: =D2 -> 0.05115 | O2: =MAX(ABS(L2-M2)) -> 0.00073
A3: 0.049884803 | B3: 0.05115 | C3: 0.049884803 | D3: 0.05115 | F3: =IF(C3<>"",A3-C3,"") -> 5.5511151e-17 | G3: =B3-D3 -> 0 | K3: 2 | L3: 0.05115 | M3: =D3 -> 0.05115 | O3: =MAX(ABS(L3-M3)) -> 0
A4: 0.048153843 | B4: 0.04933 | C4: 0.048153843 | D4: 0.04933 | F4: =IF(C4<>"",A4-C4,"") -> 3.469447e-17 | G4: =B4-D4 -> 0 | K4: 3 | L4: 0.04997 | M4: =D4 -> 0.04933 | O4: =MAX(ABS(L4-M4)) -> 0.00064
A5: 0.047288363 | B5: 0.04842 | C5: 0.047288363 | D5: 0.04842 | F5: =IF(C5<>"",A5-C5,"") -> 9.7144515e-17 | G5: =B5-D5 -> 0 | K5: 4 | L5: 0.04881 | M5: =D5 -> 0.04842 | O5: =MAX(ABS(L5-M5)) -> 0.00039
A6: 0.046769076 | B6: 0.04788 | C6: 0.046769076 | D6: 0.04788 | F6: =IF(C6<>"",A6-C6,"") -> 5.5511151e-17 | G6: =B6-D6 -> 0 | K6: 5 | L6: 0.04788 | M6: =D6 -> 0.04788 | O6: =MAX(ABS(L6-M6)) -> 0
A7: 0.045995189 | B7: 0.04707 | C7: 0.045995189 | D7: 0.04707 | F7: =IF(C7<>"",A7-C7,"") -> 9.7144515e-17 | G7: =B7-D7 -> 0 | K7: 6 | L7: 0.04719 | M7: =D7 -> 0.04707 | O7: =MAX(ABS(L7-M7)) -> 0.00012
A8: 0.045442412 | B8: 0.04649 | C8: 0.045442412 | D8: 0.04649 | F8: =IF(C8<>"",A8-C8,"") -> 6.9388939e-17 | G8: =B8-D8 -> 0 | K8: 7 | L8: 0.04667 | M8: =D8 -> 0.04649 | O8: =MAX(ABS(L8-M8)) -> 0.00018
A9: 0.04502783 | B9: 0.04606 | C9: 0.04502783 | D9: 0.04606 | F9: =IF(C9<>"",A9-C9,"") -> 0 | G9: =B9-D9 -> 0 | K9: 8 | L9: 0.04623 | M9: =D9 -> 0.04606 | O9: =MAX(ABS(L9-M9)) -> 0.00017
A10: 0.044705377 | B10: 0.04572 | C10: 0.044705377 | D10: 0.04572 | F10: =IF(C10<>"",A10-C10,"") -> 1.3877788e-17 | G10: =B10-D10 -> 0 | K10: 9 | L10: 0.04583 | M10: =D10 -> 0.04572 | O10: =MAX(ABS(L10-M10)) -> 0.00011
A11: 0.044447415 | B11: 0.04545 | C11: 0.044447415 | D11: 0.04545 | F11: =IF(C11<>"",A11-C11,"") -> 4.8572257e-17 | G11: =B11-D11 -> 0 | K11: 10 | L11: 0.04545 | M11: =D11 -> 0.04545 | O11: =MAX(ABS(L11-M11)) -> 0
A12: #N/A | B12: 0.04518 | D12: 0.04518 | F12: =IF(C12<>"",A12-C12,"") | G12: =B12-D12 -> 0 | K12: 11 | L12: 0.04508 | M12: =D12 -> 0.04518 | O12: =MAX(ABS(L12-M12)) -> 0.0001
A13: #N/A | B13: 0.04487 | D13: 0.04487 | F13: =IF(C13<>"",A13-C13,"") | G13: =B13-D13 -> 0 | K13: 12 | L13: 0.04471 | M13: =D13 -> 0.04487 | O13: =MAX(ABS(L13-M13)) -> 0.00016
A14: #N/A | B14: 0.04454 | D14: 0.04454 | F14: =IF(C14<>"",A14-C14,"") | G14: =B14-D14 -> 0 | K14: 13 | L14: 0.04435 | M14: =D14 -> 0.04454 | O14: =MAX(ABS(L14-M14)) -> 0.00019
A15: #N/A | B15: 0.04421 | D15: 0.04421 | F15: =IF(C15<>"",A15-C15,"") | G15: =B15-D15 -> 0 | K15: 14 | L15: 0.044 | M15: =D15 -> 0.04421 | O15: =MAX(ABS(L15-M15)) -> 0.00021
A16: #N/A | B16: 0.04387 | D16: 0.04387 | F16: =IF(C16<>"",A16-C16,"") | G16: =B16-D16 -> 0 | K16: 15 | L16: 0.04367 | M16: =D16 -> 0.04387 | O16: =MAX(ABS(L16-M16)) -> 0.0002
A17: #N/A | B17: 0.04353 | D17: 0.04353 | F17: =IF(C17<>"",A17-C17,"") | G17: =B17-D17 -> 0 | K17: 16 | L17: 0.04334 | M17: =D17 -> 0.04353 | O17: =MAX(ABS(L17-M17)) -> 0.00019
A18: #N/A | B18: 0.04319 | D18: 0.04319 | F18: =IF(C18<>"",A18-C18,"") | G18: =B18-D18 -> 0 | K18: 17 | L18: 0.04303 | M18: =D18 -> 0.04319 | O18: =MAX(ABS(L18-M18)) -> 0.00016
A19: #N/A | B19: 0.04287 | D19: 0.04287 | F19: =IF(C19<>"",A19-C19,"") | G19: =B19-D19 -> 0 | K19: 18 | L19: 0.04273 | M19: =D19 -> 0.04287 | O19: =MAX(ABS(L19-M19)) -> 0.00014
A20: #N/A | B20: 0.04256 | D20: 0.04256 | F20: =IF(C20<>"",A20-C20,"") | G20: =B20-D20 -> 0 | K20: 19 | L20: 0.04244 | M20: =D20 -> 0.04256 | O20: =MAX(ABS(L20-M20)) -> 0.00012
A21: #N/A | B21: 0.04225 | D21: 0.04225 | F21: =IF(C21<>"",A21-C21,"") | G21: =B21-D21 -> 0 | K21: 20 | L21: 0.04216 | M21: =D21 -> 0.04225 | O21: =MAX(ABS(L21-M21)) -> 9e-05
A22: #N/A | B22: 0.04196 | D22: 0.04196 | F22: =IF(C22<>"",A22-C22,"") | G22: =B22-D22 -> 0 | K22: 21 | L22: 0.04189 | M22: =D22 -> 0.04196 | O22: =MAX(ABS(L22-M22)) -> 7e-05
A23: #N/A | B23: 0.04168 | D23: 0.04168 | F23: =IF(C23<>"",A23-C23,"") | G23: =B23-D23 -> 0 | K23: 22 | L23: 0.04164 | M23: =D23 -> 0.04168 | O23: =MAX(ABS(L23-M23)) -> 4e-05
... A151: #N/A | B151: 0.03443 | D151: 0.03443 | F151: =IF(C151<>"",A151-C151,"") | G151: =B151-D151 -> 0 | K151: 150 | L151: 0.0345 | M151: =D151 -> 0.03443 | O151: =MAX(ABS(L151-M151)) -> 7e-05

Sheet Canada
A1: Bootstrapped Zero Rate CC | B1: Extrapolated Zero Rate AC / Basic RFR | C1: Bootstrapped Zero Rate CC | D1: Basic RFR | F1: =SUM(F2:F151) -> 1.4918622e-15 | G1: =SUM(G2:G151) -> 0 | K1: Maturity | L1: Smith-Wilson | M1: Constant forward | O1: =MAX(O2:O151) -> 0.00049 | P1: =MAX(O2:O51) -> 0.00049
A2: 0.029257786 | B2: 0.02969 | C2: 0.029257786 | D2: 0.02969 | F2: =IF(C2<>"",A2-C2,"") -> 4.1633363e-17 | G2: =B2-D2 -> 0 | K2: 1 | L2: 0.02969 | M2: =D2 -> 0.02969 | O2: =MAX(ABS(L2-M2)) -> 0
A3: 0.032912396 | B3: 0.03346 | C3: 0.032912396 | D3: 0.03346 | F3: =IF(C3<>"",A3-C3,"") -> 4.1633363e-17 | G3: =B3-D3 -> 0 | K3: 2 | L3: 0.03346 | M3: =D3 -> 0.03346 | O3: =MAX(ABS(L3-M3)) -> 0
A4: 0.034304804 | B4: 0.0349 | C4: 0.034304804 | D4: 0.0349 | F4: =IF(C4<>"",A4-C4,"") -> 6.9388939e-17 | G4: =B4-D4 -> 0 | K4: 3 | L4: 0.0349 | M4: =D4 -> 0.0349 | O4: =MAX(ABS(L4-M4)) -> 0
A5: 0.034710558 | B5: 0.03532 | C5: 0.034710558 | D5: 0.03532 | F5: =IF(C5<>"",A5-C5,"") -> 8.3266727e-17 | G5: =B5-D5 -> 0 | K5: 4 | L5: 0.03532 | M5: =D5 -> 0.03532 | O5: =MAX(ABS(L5-M5)) -> 0
A6: 0.035289921 | B6: 0.03592 | C6: 0.035289921 | D6: 0.03592 | F6: =IF(C6<>"",A6-C6,"") -> 4.8572257e-17 | G6: =B6-D6 -> 0 | K6: 5 | L6: 0.03592 | M6: =D6 -> 0.03592 | O6: =MAX(ABS(L6-M6)) -> 0
A7: 0.036164002 | B7: 0.03683 | C7: 0.036164002 | D7: 0.03683 | F7: =IF(C7<>"",A7-C7,"") -> 0 | G7: =B7-D7 -> 0 | K7: 6 | L7: 0.03656 | M7: =D7 -> 0.03683 | O7: =MAX(ABS(L7-M7)) -> 0.00027
A8: 0.036788346 | B8: 0.03747 | C8: 0.036788346 | D8: 0.03747 | F8: =IF(C8<>"",A8-C8,"") -> 5.5511151e-17 | G8: =B8-D8 -> 0 | K8: 7 | L8: 0.03715 | M8: =D8 -> 0.03747 | O8: =MAX(ABS(L8-M8)) -> 0.00032
A9: 0.037256604 | B9: 0.03796 | C9: 0.037256604 | D9: 0.03796 | F9: =IF(C9<>"",A9-C9,"") -> 2.0816682e-17 | G9: =B9-D9 -> 0 | K9: 8 | L9: 0.03769 | M9: =D9 -> 0.03796 | O9: =MAX(ABS(L9-M9)) -> 0.00027
A10: 0.037620805 | B10: 0.03834 | C10: 0.037620805 | D10: 0.03834 | F10: =IF(C10<>"",A10-C10,"") -> 6.2450045e-17 | G10: =B10-D10 -> 0 | K10: 9 | L10: 0.03819 | M10: =D10 -> 0.03834 | O10: =MAX(ABS(L10-M10)) -> 0.00015
A11: 0.037912165 | B11: 0.03864 | C11: 0.037912165 | D11: 0.03864 | F11: =IF(C11<>"",A11-C11,"") -> 9.0205621e-17 | G11: =B11-D11 -> 0 | K11: 10 | L11: 0.03864 | M11: =D11 -> 0.03864 | O11: =MAX(ABS(L11-M11)) -> 0
A12: 0.038297614 | B12: 0.03904 | C12: 0.038297614 | D12: 0.03904 | F12: =IF(C12<>"",A12-C12,"") -> 8.3266727e-17 | G12: =B12-D12 -> 0 | K12: 11 | L12: 0.03905 | M12: =D12 -> 0.03904 | O12: =MAX(ABS(L12-M12)) -> 1e-05
A13: 0.038618822 | B13: 0.03937 | C13: 0.038618822 | D13: 0.03937 | F13: =IF(C13<>"",A13-C13,"") -> 6.9388939e-18 | G13: =B13-D13 -> 0 | K13: 12 | L13: 0.03942 | M13: =D13 -> 0.03937 | O13: =MAX(ABS(L13-M13)) -> 5e-05
... A31: 0.040738791 | B31: 0.04158 | C31: 0.040738791 | D31: 0.04158 | F31: =IF(C31<>"",A31-C31,"") -> 6.9388939e-18 | G31: =B31-D31 -> 0 | K31: 30 | L31: 0.04158 | M31: =D31 -> 0.04158 | O31: =MAX(ABS(L31-M31)) -> 0
A32: #N/A | B32: 0.04161 | D32: 0.04161 | F32: =IF(C32<>"",A32-C32,"") | G32: =B32-D32 -> 0 | K32: 31 | L32: 0.04151 | M32: =D32 -> 0.04161 | O32: =MAX(ABS(L32-M32)) -> 0.0001
A33: #N/A | B33: 0.04161 | D33: 0.04161 | F33: =IF(C33<>"",A33-C33,"") | G33: =B33-D33 -> 0 | K33: 32 | L33: 0.04143 | M33: =D33 -> 0.04161 | O33: =MAX(ABS(L33-M33)) -> 0.00018
A34: #N/A | B34: 0.04158 | D34: 0.04158 | F34: =IF(C34<>"",A34-C34,"") | G34: =B34-D34 -> 0 | K34: 33 | L34: 0.04133 | M34: =D34 -> 0.04158 | O34: =MAX(ABS(L34-M34)) -> 0.00025
A35: #N/A | B35: 0.04153 | D35: 0.04153 | F35: =IF(C35<>"",A35-C35,"") | G35: =B35-D35 -> 0 | K35: 34 | L35: 0.04122 | M35: =D35 -> 0.04153 | O35: =MAX(ABS(L35-M35)) -> 0.00031
A36: #N/A | B36: 0.04146 | D36: 0.04146 | F36: =IF(C36<>"",A36-C36,"") | G36: =B36-D36 -> 0 | K36: 35 | L36: 0.04111 | M36: =D36 -> 0.04146 | O36: =MAX(ABS(L36-M36)) -> 0.00035
A37: #N/A | B37: 0.04137 | D37: 0.04137 | F37: =IF(C37<>"",A37-C37,"") | G37: =B37-D37 -> 0 | K37: 36 | L37: 0.04099 | M37: =D37 -> 0.04137 | O37: =MAX(ABS(L37-M37)) -> 0.00038
A38: #N/A | B38: 0.04128 | D38: 0.04128 | F38: =IF(C38<>"",A38-C38,"") | G38: =B38-D38 -> 0 | K38: 37 | L38: 0.04087 | M38: =D38 -> 0.04128 | O38: =MAX(ABS(L38-M38)) -> 0.00041
A39: #N/A | B39: 0.04118 | D39: 0.04118 | F39: =IF(C39<>"",A39-C39,"") | G39: =B39-D39 -> 0 | K39: 38 | L39: 0.04074 | M39: =D39 -> 0.04118 | O39: =MAX(ABS(L39-M39)) -> 0.00044
A40: #N/A | B40: 0.04107 | D40: 0.04107 | F40: =IF(C40<>"",A40-C40,"") | G40: =B40-D40 -> 0 | K40: 39 | L40: 0.04062 | M40: =D40 -> 0.04107 | O40: =MAX(ABS(L40-M40)) -> 0.00045
A41: #N/A | B41: 0.04096 | D41: 0.04096 | F41: =IF(C41<>"",A41-C41,"") | G41: =B41-D41 -> 0 | K41: 40 | L41: 0.04049 | M41: =D41 -> 0.04096 | O41: =MAX(ABS(L41-M41)) -> 0.00047
A42: #N/A | B42: 0.04084 | D42: 0.04084 | F42: =IF(C42<>"",A42-C42,"") | G42: =B42-D42 -> 0 | K42: 41 | L42: 0.04036 | M42: =D42 -> 0.04084 | O42: =MAX(ABS(L42-M42)) -> 0.00048
A43: #N/A | B43: 0.04072 | D43: 0.04072 | F43: =IF(C43<>"",A43-C43,"") | G43: =B43-D43 -> 0 | K43: 42 | L43: 0.04024 | M43: =D43 -> 0.04072 | O43: =MAX(ABS(L43-M43)) -> 0.00048
... A151: #N/A | B151: 0.03532 | D151: 0.03532 | F151: =IF(C151<>"",A151-C151,"") | G151: =B151-D151 -> 0 | K151: 150 | L151: 0.03515 | M151: =D151 -> 0.03532 | O151: =MAX(ABS(L151-M151)) -> 0.00017

Sheet Poland
A1: Bootstrapped Zero Rate CC | B1: Extrapolated Zero Rate AC / Basic RFR | C1: Bootstrapped Zero Rate CC | D1: Basic RFR | F1: =SUM(F2:F151) -> 4.4408921e-16 | G1: =SUM(G2:G151) -> 0 | K1: Maturity | L1: Smith-Wilson | M1: Constant forward | O1: =MAX(O2:O151) -> 0.0004 | P1: =MAX(O2:O51) -> 0.0004
A2: 0.041055567 | B2: 0.04191 | C2: 0.041055567 | D2: 0.04191 | F2: =IF(C2<>"",A2-C2,"") -> 0 | G2: =B2-D2 -> 0 | K2: 1 | L2: 0.04191 | M2: =D2 -> 0.04191 | O2: =MAX(ABS(L2-M2)) -> 0
A3: 0.047579908 | B3: 0.04873 | C3: 0.047579908 | D3: 0.04873 | F3: =IF(C3<>"",A3-C3,"") -> 2.7755576e-17 | G3: =B3-D3 -> 0 | K3: 2 | L3: 0.04873 | M3: =D3 -> 0.04873 | O3: =MAX(ABS(L3-M3)) -> 0
A4: 0.051804664 | B4: 0.05317 | C4: 0.051804664 | D4: 0.05317 | F4: =IF(C4<>"",A4-C4,"") -> 5.5511151e-17 | G4: =B4-D4 -> 0 | K4: 3 | L4: 0.05317 | M4: =D4 -> 0.05317 | O4: =MAX(ABS(L4-M4)) -> 0
A5: 0.054573409 | B5: 0.05609 | C5: 0.054573409 | D5: 0.05609 | F5: =IF(C5<>"",A5-C5,"") -> 2.0816682e-17 | G5: =B5-D5 -> 0 | K5: 4 | L5: 0.05609 | M5: =D5 -> 0.05609 | O5: =MAX(ABS(L5-M5)) -> 0
A6: 0.056550451 | B6: 0.05818 | C6: 0.056550451 | D6: 0.05818 | F6: =IF(C6<>"",A6-C6,"") -> 6.9388939e-17 | G6: =B6-D6 -> 0 | K6: 5 | L6: 0.05818 | M6: =D6 -> 0.05818 | O6: =MAX(ABS(L6-M6)) -> 0
A7: 0.058108518 | B7: 0.05983 | C7: 0.058108518 | D7: 0.05983 | F7: =IF(C7<>"",A7-C7,"") -> 2.7755576e-17 | G7: =B7-D7 -> 0 | K7: 6 | L7: 0.05983 | M7: =D7 -> 0.05983 | O7: =MAX(ABS(L7-M7)) -> 0
A8: 0.059240134 | B8: 0.06103 | C8: 0.059240134 | D8: 0.06103 | F8: =IF(C8<>"",A8-C8,"") -> 2.0816682e-17 | G8: =B8-D8 -> 0 | K8: 7 | L8: 0.06103 | M8: =D8 -> 0.06103 | O8: =MAX(ABS(L8-M8)) -> 0
A9: 0.060163339 | B9: 0.06201 | C9: 0.060163339 | D9: 0.06201 | F9: =IF(C9<>"",A9-C9,"") -> 9.0205621e-17 | G9: =B9-D9 -> 0 | K9: 8 | L9: 0.06201 | M9: =D9 -> 0.06201 | O9: =MAX(ABS(L9-M9)) -> 0
A10: 0.060953979 | B10: 0.06285 | C10: 0.060953979 | D10: 0.06285 | F10: =IF(C10<>"",A10-C10,"") -> 6.2450045e-17 | G10: =B10-D10 -> 0 | K10: 9 | L10: 0.06285 | M10: =D10 -> 0.06285 | O10: =MAX(ABS(L10-M10)) -> 0
A11: 0.061612369 | B11: 0.06355 | C11: 0.061612369 | D11: 0.06355 | F11: =IF(C11<>"",A11-C11,"") -> 6.9388939e-17 | G11: =B11-D11 -> 0 | K11: 10 | L11: 0.06355 | M11: =D11 -> 0.06355 | O11: =MAX(ABS(L11-M11)) -> 0
A12: #N/A | B12: 0.06394 | D12: 0.06394 | F12: =IF(C12<>"",A12-C12,"") | G12: =B12-D12 -> 0 | K12: 11 | L12: 0.06391 | M12: =D12 -> 0.06394 | O12: =MAX(ABS(L12-M12)) -> 3e-05
A13: #N/A | B13: 0.06396 | D13: 0.06396 | F13: =IF(C13<>"",A13-C13,"") | G13: =B13-D13 -> 0 | K13: 12 | L13: 0.06394 | M13: =D13 -> 0.06396 | O13: =MAX(ABS(L13-M13)) -> 2e-05
A14: #N/A | B14: 0.06373 | D14: 0.06373 | F14: =IF(C14<>"",A14-C14,"") | G14: =B14-D14 -> 0 | K14: 13 | L14: 0.06375 | M14: =D14 -> 0.06373 | O14: =MAX(ABS(L14-M14)) -> 2e-05
A15: #N/A | B15: 0.06332 | D15: 0.06332 | F15: =IF(C15<>"",A15-C15,"") | G15: =B15-D15 -> 0 | K15: 14 | L15: 0.0634 | M15: =D15 -> 0.06332 | O15: =MAX(ABS(L15-M15)) -> 8e-05
A16: #N/A | B16: 0.06278 | D16: 0.06278 | F16: =IF(C16<>"",A16-C16,"") | G16: =B16-D16 -> 0 | K16: 15 | L16: 0.06293 | M16: =D16 -> 0.06278 | O16: =MAX(ABS(L16-M16)) -> 0.00015
A17: #N/A | B17: 0.06217 | D17: 0.06217 | F17: =IF(C17<>"",A17-C17,"") | G17: =B17-D17 -> 0 | K17: 16 | L17: 0.06237 | M17: =D17 -> 0.06217 | O17: =MAX(ABS(L17-M17)) -> 0.0002
A18: #N/A | B18: 0.0615 | D18: 0.0615 | F18: =IF(C18<>"",A18-C18,"") | G18: =B18-D18 -> 0 | K18: 17 | L18: 0.06176 | M18: =D18 -> 0.0615 | O18: =MAX(ABS(L18-M18)) -> 0.00026
A19: #N/A | B19: 0.0608 | D19: 0.0608 | F19: =IF(C19<>"",A19-C19,"") | G19: =B19-D19 -> 0 | K19: 18 | L19: 0.0611 | M19: =D19 -> 0.0608 | O19: =MAX(ABS(L19-M19)) -> 0.0003
A20: #N/A | B20: 0.06009 | D20: 0.06009 | F20: =IF(C20<>"",A20-C20,"") | G20: =B20-D20 -> 0 | K20: 19 | L20: 0.06042 | M20: =D20 -> 0.06009 | O20: =MAX(ABS(L20-M20)) -> 0.00033
A21: #N/A | B21: 0.05937 | D21: 0.05937 | F21: =IF(C21<>"",A21-C21,"") | G21: =B21-D21 -> 0 | K21: 20 | L21: 0.05973 | M21: =D21 -> 0.05937 | O21: =MAX(ABS(L21-M21)) -> 0.00036
A22: #N/A | B22: 0.05866 | D22: 0.05866 | F22: =IF(C22<>"",A22-C22,"") | G22: =B22-D22 -> 0 | K22: 21 | L22: 0.05904 | M22: =D22 -> 0.05866 | O22: =MAX(ABS(L22-M22)) -> 0.00038
A23: #N/A | B23: 0.05795 | D23: 0.05795 | F23: =IF(C23<>"",A23-C23,"") | G23: =B23-D23 -> 0 | K23: 22 | L23: 0.05835 | M23: =D23 -> 0.05795 | O23: =MAX(ABS(L23-M23)) -> 0.0004
... A151: #N/A | B151: 0.03721 | D151: 0.03721 | F151: =IF(C151<>"",A151-C151,"") | G151: =B151-D151 -> 0 | K151: 150 | L151: 0.03726 | M151: =D151 -> 0.03721 | O151: =MAX(ABS(L151-M151)) -> 5e-05

Sheet Japan
A1: Bootstrapped Zero Rate CC | B1: Extrapolated Zero Rate AC / Basic RFR | C1: Bootstrapped Zero Rate CC | D1: Basic RFR | F1: =SUM(F2:F151) -> 1.5508428e-15 | G1: =SUM(G2:G151) -> 0 | K1: Maturity | L1: Smith-Wilson | M1: Constant forward | O1: =MAX(O2:O151) -> 0.00043 | P1: =MAX(O2:O51) -> 0.00043
A2: 0.016630936 | B2: 0.01677 | C2: 0.016630936 | D2: 0.01677 | F2: =IF(C2<>"",A2-C2,"") -> 3.1225023e-17 | G2: =B2-D2 -> 0 | K2: 1 | L2: 0.01677 | M2: =D2 -> 0.01677 | O2: =MAX(ABS(L2-M2)) -> 0
A3: 0.019439816 | B3: 0.01963 | C3: 0.019439816 | D3: 0.01963 | F3: =IF(C3<>"",A3-C3,"") -> 1.3877788e-17 | G3: =B3-D3 -> 0 | K3: 2 | L3: 0.01963 | M3: =D3 -> 0.01963 | O3: =MAX(ABS(L3-M3)) -> 0
A4: 0.021164445 | B4: 0.02139 | C4: 0.021164445 | D4: 0.02139 | F4: =IF(C4<>"",A4-C4,"") -> 7.6327833e-17 | G4: =B4-D4 -> 0 | K4: 3 | L4: 0.02139 | M4: =D4 -> 0.02139 | O4: =MAX(ABS(L4-M4)) -> 0
A5: 0.022814425 | B5: 0.02308 | C5: 0.022814425 | D5: 0.02308 | F5: =IF(C5<>"",A5-C5,"") -> 5.5511151e-17 | G5: =B5-D5 -> 0 | K5: 4 | L5: 0.02279 | M5: =D5 -> 0.02308 | O5: =MAX(ABS(L5-M5)) -> 0.00029
A6: 0.023804413 | B6: 0.02409 | C6: 0.023804413 | D6: 0.02409 | F6: =IF(C6<>"",A6-C6,"") -> 6.5919492e-17 | G6: =B6-D6 -> 0 | K6: 5 | L6: 0.02409 | M6: =D6 -> 0.02409 | O6: =MAX(ABS(L6-M6)) -> 0
A7: 0.025186929 | B7: 0.02551 | C7: 0.025186929 | D7: 0.02551 | F7: =IF(C7<>"",A7-C7,"") -> 8.3266727e-17 | G7: =B7-D7 -> 0 | K7: 6 | L7: 0.02533 | M7: =D7 -> 0.02551 | O7: =MAX(ABS(L7-M7)) -> 0.00018
A8: 0.026174441 | B8: 0.02652 | C8: 0.026174441 | D8: 0.02652 | F8: =IF(C8<>"",A8-C8,"") -> 9.0205621e-17 | G8: =B8-D8 -> 0 | K8: 7 | L8: 0.02652 | M8: =D8 -> 0.02652 | O8: =MAX(ABS(L8-M8)) -> 0
A9: 0.027519862 | B9: 0.0279 | C9: 0.027519862 | D9: 0.0279 | F9: =IF(C9<>"",A9-C9,"") -> 2.0816682e-17 | G9: =B9-D9 -> 0 | K9: 8 | L9: 0.02768 | M9: =D9 -> 0.0279 | O9: =MAX(ABS(L9-M9)) -> 0.00022
A10: 0.0285663 | B10: 0.02898 | C10: 0.0285663 | D10: 0.02898 | F10: =IF(C10<>"",A10-C10,"") -> 4.510281e-17 | G10: =B10-D10 -> 0 | K10: 9 | L10: 0.02879 | M10: =D10 -> 0.02898 | O10: =MAX(ABS(L10-M10)) -> 0.00019
A11: 0.02940345 | B11: 0.02984 | C11: 0.02940345 | D11: 0.02984 | F11: =IF(C11<>"",A11-C11,"") -> 7.979728e-17 | G11: =B11-D11 -> 0 | K11: 10 | L11: 0.02984 | M11: =D11 -> 0.02984 | O11: =MAX(ABS(L11-M11)) -> 0
A12: 0.030619336 | B12: 0.03109 | C12: 0.030619336 | D12: 0.03109 | F12: =IF(C12<>"",A12-C12,"") -> 4.510281e-17 | G12: =B12-D12 -> 0 | K12: 11 | L12: 0.03083 | M12: =D12 -> 0.03109 | O12: =MAX(ABS(L12-M12)) -> 0.00026
A13: 0.031632574 | B13: 0.03214 | C13: 0.031632574 | D13: 0.03214 | F13: =IF(C13<>"",A13-C13,"") -> 4.1633363e-17 | G13: =B13-D13 -> 0 | K13: 12 | L13: 0.03175 | M13: =D13 -> 0.03214 | O13: =MAX(ABS(L13-M13)) -> 0.00039
... A31: 0.037729217 | B31: 0.03845 | C31: 0.037729217 | D31: 0.03845 | F31: =IF(C31<>"",A31-C31,"") -> 6.2450045e-17 | G31: =B31-D31 -> 0 | K31: 30 | L31: 0.03845 | M31: =D31 -> 0.03845 | O31: =MAX(ABS(L31-M31)) -> 0
A32: #N/A | B32: 0.03854 | D32: 0.03854 | F32: =IF(C32<>"",A32-C32,"") | G32: =B32-D32 -> 0 | K32: 31 | L32: 0.03845 | M32: =D32 -> 0.03854 | O32: =MAX(ABS(L32-M32)) -> 9e-05
A33: #N/A | B33: 0.0386 | D33: 0.0386 | F33: =IF(C33<>"",A33-C33,"") | G33: =B33-D33 -> 0 | K33: 32 | L33: 0.03844 | M33: =D33 -> 0.0386 | O33: =MAX(ABS(L33-M33)) -> 0.00016
A34: #N/A | B34: 0.03863 | D34: 0.03863 | F34: =IF(C34<>"",A34-C34,"") | G34: =B34-D34 -> 0 | K34: 33 | L34: 0.03841 | M34: =D34 -> 0.03863 | O34: =MAX(ABS(L34-M34)) -> 0.00022
A35: #N/A | B35: 0.03863 | D35: 0.03863 | F35: =IF(C35<>"",A35-C35,"") | G35: =B35-D35 -> 0 | K35: 34 | L35: 0.03836 | M35: =D35 -> 0.03863 | O35: =MAX(ABS(L35-M35)) -> 0.00027
A36: #N/A | B36: 0.03861 | D36: 0.03861 | F36: =IF(C36<>"",A36-C36,"") | G36: =B36-D36 -> 0 | K36: 35 | L36: 0.0383 | M36: =D36 -> 0.03861 | O36: =MAX(ABS(L36-M36)) -> 0.00031
A37: #N/A | B37: 0.03858 | D37: 0.03858 | F37: =IF(C37<>"",A37-C37,"") | G37: =B37-D37 -> 0 | K37: 36 | L37: 0.03824 | M37: =D37 -> 0.03858 | O37: =MAX(ABS(L37-M37)) -> 0.00034
A38: #N/A | B38: 0.03853 | D38: 0.03853 | F38: =IF(C38<>"",A38-C38,"") | G38: =B38-D38 -> 0 | K38: 37 | L38: 0.03817 | M38: =D38 -> 0.03853 | O38: =MAX(ABS(L38-M38)) -> 0.00036
A39: #N/A | B39: 0.03847 | D39: 0.03847 | F39: =IF(C39<>"",A39-C39,"") | G39: =B39-D39 -> 0 | K39: 38 | L39: 0.03809 | M39: =D39 -> 0.03847 | O39: =MAX(ABS(L39-M39)) -> 0.00038
A40: #N/A | B40: 0.0384 | D40: 0.0384 | F40: =IF(C40<>"",A40-C40,"") | G40: =B40-D40 -> 0 | K40: 39 | L40: 0.03801 | M40: =D40 -> 0.0384 | O40: =MAX(ABS(L40-M40)) -> 0.00039
A41: #N/A | B41: 0.03833 | D41: 0.03833 | F41: =IF(C41<>"",A41-C41,"") | G41: =B41-D41 -> 0 | K41: 40 | L41: 0.03792 | M41: =D41 -> 0.03833 | O41: =MAX(ABS(L41-M41)) -> 0.00041
A42: #N/A | B42: 0.03825 | D42: 0.03825 | F42: =IF(C42<>"",A42-C42,"") | G42: =B42-D42 -> 0 | K42: 41 | L42: 0.03783 | M42: =D42 -> 0.03825 | O42: =MAX(ABS(L42-M42)) -> 0.00042
A43: #N/A | B43: 0.03817 | D43: 0.03817 | F43: =IF(C43<>"",A43-C43,"") | G43: =B43-D43 -> 0 | K43: 42 | L43: 0.03775 | M43: =D43 -> 0.03817 | O43: =MAX(ABS(L43-M43)) -> 0.00042
... A151: #N/A | B151: 0.03388 | D151: 0.03388 | F151: =IF(C151<>"",A151-C151,"") | G151: =B151-D151 -> 0 | K151: 150 | L151: 0.03373 | M151: =D151 -> 0.03388 | O151: =MAX(ABS(L151-M151)) -> 0.00015

Sheet Czechia
A1: Bootstrapped Zero Rate CC | B1: Extrapolated Zero Rate AC / Basic RFR | C1: Bootstrapped Zero Rate CC | D1: Basic RFR | F1: =SUM(F2:F151) -> 1.0269563e-15 | G1: =SUM(G2:G151) -> 0 | K1: Maturity | L1: Smith-Wilson | M1: Constant forward | O1: =MAX(O2:O151) -> 0.00039 | P1: =MAX(O2:O51) -> 0.00039
A2: 0.042369596 | B2: 0.04328 | C2: 0.042369596 | D2: 0.04328 | F2: =IF(C2<>"",A2-C2,"") -> 5.5511151e-17 | G2: =B2-D2 -> 0 | K2: 1 | L2: 0.04328 | M2: =D2 -> 0.04328 | O2: =MAX(ABS(L2-M2)) -> 0
A3: 0.045470374 | B3: 0.04652 | C3: 0.045470374 | D3: 0.04652 | F3: =IF(C3<>"",A3-C3,"") -> 7.6327833e-17 | G3: =B3-D3 -> 0 | K3: 2 | L3: 0.04652 | M3: =D3 -> 0.04652 | O3: =MAX(ABS(L3-M3)) -> 0
A4: 0.04667364 | B4: 0.04778 | C4: 0.04667364 | D4: 0.04778 | F4: =IF(C4<>"",A4-C4,"") -> 9.7144515e-17 | G4: =B4-D4 -> 0 | K4: 3 | L4: 0.04778 | M4: =D4 -> 0.04778 | O4: =MAX(ABS(L4-M4)) -> 0
A5: 0.047085089 | B5: 0.04821 | C5: 0.047085089 | D5: 0.04821 | F5: =IF(C5<>"",A5-C5,"") -> 4.1633363e-17 | G5: =B5-D5 -> 0 | K5: 4 | L5: 0.04824 | M5: =D5 -> 0.04821 | O5: =MAX(ABS(L5-M5)) -> 3e-05
A6: 0.047331959 | B6: 0.04847 | C6: 0.047331959 | D6: 0.04847 | F6: =IF(C6<>"",A6-C6,"") -> 4.8572257e-17 | G6: =B6-D6 -> 0 | K6: 5 | L6: 0.04847 | M6: =D6 -> 0.04847 | O6: =MAX(ABS(L6-M6)) -> 0
A7: 0.047646554 | B7: 0.0488 | C7: 0.047646554 | D7: 0.0488 | F7: =IF(C7<>"",A7-C7,"") -> 9.0205621e-17 | G7: =B7-D7 -> 0 | K7: 6 | L7: 0.04862 | M7: =D7 -> 0.0488 | O7: =MAX(ABS(L7-M7)) -> 0.00018
A8: 0.047871266 | B8: 0.04904 | C8: 0.047871266 | D8: 0.04904 | F8: =IF(C8<>"",A8-C8,"") -> 7.6327833e-17 | G8: =B8-D8 -> 0 | K8: 7 | L8: 0.04877 | M8: =D8 -> 0.04904 | O8: =MAX(ABS(L8-M8)) -> 0.00027
A9: 0.048039799 | B9: 0.04921 | C9: 0.048039799 | D9: 0.04921 | F9: =IF(C9<>"",A9-C9,"") -> 9.0205621e-17 | G9: =B9-D9 -> 0 | K9: 8 | L9: 0.04895 | M9: =D9 -> 0.04921 | O9: =MAX(ABS(L9-M9)) -> 0.00026
A10: 0.048170881 | B10: 0.04935 | C10: 0.048170881 | D10: 0.04935 | F10: =IF(C10<>"",A10-C10,"") -> 9.7144515e-17 | G10: =B10-D10 -> 0 | K10: 9 | L10: 0.04918 | M10: =D10 -> 0.04935 | O10: =MAX(ABS(L10-M10)) -> 0.00017
A11: 0.048275746 | B11: 0.04946 | C11: 0.048275746 | D11: 0.04946 | F11: =IF(C11<>"",A11-C11,"") -> 8.3266727e-17 | G11: =B11-D11 -> 0 | K11: 10 | L11: 0.04946 | M11: =D11 -> 0.04946 | O11: =MAX(ABS(L11-M11)) -> 0
A12: 0.048623755 | B12: 0.04983 | C12: 0.048623755 | D12: 0.04983 | F12: =IF(C12<>"",A12-C12,"") -> 4.8572257e-17 | G12: =B12-D12 -> 0 | K12: 11 | L12: 0.04981 | M12: =D12 -> 0.04983 | O12: =MAX(ABS(L12-M12)) -> 2e-05
A13: 0.048913762 | B13: 0.05013 | C13: 0.048913762 | D13: 0.05013 | F13: =IF(C13<>"",A13-C13,"") -> 5.5511151e-17 | G13: =B13-D13 -> 0 | K13: 12 | L13: 0.05015 | M13: =D13 -> 0.05013 | O13: =MAX(ABS(L13-M13)) -> 2e-05
... A16: 0.049551779 | B16: 0.0508 | C16: 0.049551779 | D16: 0.0508 | F16: =IF(C16<>"",A16-C16,"") -> 2.7755576e-17 | G16: =B16-D16 -> 0 | K16: 15 | L16: 0.0508 | M16: =D16 -> 0.0508 | O16: =MAX(ABS(L16-M16)) -> 0
A17: #N/A | B17: 0.0509 | D17: 0.0509 | F17: =IF(C17<>"",A17-C17,"") | G17: =B17-D17 -> 0 | K17: 16 | L17: 0.05079 | M17: =D17 -> 0.0509 | O17: =MAX(ABS(L17-M17)) -> 0.00011
A18: #N/A | B18: 0.05087 | D18: 0.05087 | F18: =IF(C18<>"",A18-C18,"") | G18: =B18-D18 -> 0 | K18: 17 | L18: 0.05068 | M18: =D18 -> 0.05087 | O18: =MAX(ABS(L18-M18)) -> 0.00019
A19: #N/A | B19: 0.05074 | D19: 0.05074 | F19: =IF(C19<>"",A19-C19,"") | G19: =B19-D19 -> 0 | K19: 18 | L19: 0.05049 | M19: =D19 -> 0.05074 | O19: =MAX(ABS(L19-M19)) -> 0.00025
A20: #N/A | B20: 0.05053 | D20: 0.05053 | F20: =IF(C20<>"",A20-C20,"") | G20: =B20-D20 -> 0 | K20: 19 | L20: 0.05025 | M20: =D20 -> 0.05053 | O20: =MAX(ABS(L20-M20)) -> 0.00028
A21: #N/A | B21: 0.05028 | D21: 0.05028 | F21: =IF(C21<>"",A21-C21,"") | G21: =B21-D21 -> 0 | K21: 20 | L21: 0.04996 | M21: =D21 -> 0.05028 | O21: =MAX(ABS(L21-M21)) -> 0.00032
A22: #N/A | B22: 0.04999 | D22: 0.04999 | F22: =IF(C22<>"",A22-C22,"") | G22: =B22-D22 -> 0 | K22: 21 | L22: 0.04965 | M22: =D22 -> 0.04999 | O22: =MAX(ABS(L22-M22)) -> 0.00034
A23: #N/A | B23: 0.04967 | D23: 0.04967 | F23: =IF(C23<>"",A23-C23,"") | G23: =B23-D23 -> 0 | K23: 22 | L23: 0.04931 | M23: =D23 -> 0.04967 | O23: =MAX(ABS(L23-M23)) -> 0.00036
A24: #N/A | B24: 0.04933 | D24: 0.04933 | F24: =IF(C24<>"",A24-C24,"") | G24: =B24-D24 -> 0 | K24: 23 | L24: 0.04896 | M24: =D24 -> 0.04933 | O24: =MAX(ABS(L24-M24)) -> 0.00037
A25: #N/A | B25: 0.04898 | D25: 0.04898 | F25: =IF(C25<>"",A25-C25,"") | G25: =B25-D25 -> 0 | K25: 24 | L25: 0.04861 | M25: =D25 -> 0.04898 | O25: =MAX(ABS(L25-M25)) -> 0.00037
A26: #N/A | B26: 0.04863 | D26: 0.04863 | F26: =IF(C26<>"",A26-C26,"") | G26: =B26-D26 -> 0 | K26: 25 | L26: 0.04825 | M26: =D26 -> 0.04863 | O26: =MAX(ABS(L26-M26)) -> 0.00038
A27: #N/A | B27: 0.04827 | D27: 0.04827 | F27: =IF(C27<>"",A27-C27,"") | G27: =B27-D27 -> 0 | K27: 26 | L27: 0.04789 | M27: =D27 -> 0.04827 | O27: =MAX(ABS(L27-M27)) -> 0.00038
A28: #N/A | B28: 0.04792 | D28: 0.04792 | F28: =IF(C28<>"",A28-C28,"") | G28: =B28-D28 -> 0 | K28: 27 | L28: 0.04753 | M28: =D28 -> 0.04792 | O28: =MAX(ABS(L28-M28)) -> 0.00039
... A151: #N/A | B151: 0.036 | D151: 0.036 | F151: =IF(C151<>"",A151-C151,"") | G151: =B151-D151 -> 0 | K151: 150 | L151: 0.03589 | M151: =D151 -> 0.036 | O151: =MAX(ABS(L151-M151)) -> 0.00011

Sheet UK
A1: Bootstrapped Zero Rate CC | B1: Extrapolated Zero Rate AC / Basic RFR | C1: Bootstrapped Zero Rate CC | D1: Basic RFR | F1: =SUM(F2:F151) -> 2.4563684e-15 | G1: =SUM(G2:G151) -> 0 | K1: Maturity | L1: Smith-Wilson | M1: Constant forward | O1: =MAX(O2:O151) -> 0.0004 | P1: =MAX(O2:O51) -> 0.0004
A2: 0.043576597 | B2: 0.04454 | C2: 0.043576597 | D2: 0.04454 | F2: =IF(C2<>"",A2-C2,"") -> 7.6327833e-17 | G2: =B2-D2 -> 0 | K2: 1 | L2: 0.04454 | M2: =D2 -> 0.04454 | O2: =MAX(ABS(L2-M2)) -> 0
A3: 0.045785655 | B3: 0.04685 | C3: 0.045785655 | D3: 0.04685 | F3: =IF(C3<>"",A3-C3,"") -> 2.7755576e-17 | G3: =B3-D3 -> 0 | K3: 2 | L3: 0.04685 | M3: =D3 -> 0.04685 | O3: =MAX(ABS(L3-M3)) -> 0
A4: 0.046329998 | B4: 0.04742 | C4: 0.046329998 | D4: 0.04742 | F4: =IF(C4<>"",A4-C4,"") -> 3.469447e-17 | G4: =B4-D4 -> 0 | K4: 3 | L4: 0.04742 | M4: =D4 -> 0.04742 | O4: =MAX(ABS(L4-M4)) -> 0
A5: 0.046540015 | B5: 0.04764 | C5: 0.046540015 | D5: 0.04764 | F5: =IF(C5<>"",A5-C5,"") -> 2.0816682e-17 | G5: =B5-D5 -> 0 | K5: 4 | L5: 0.04764 | M5: =D5 -> 0.04764 | O5: =MAX(ABS(L5-M5)) -> 0
A6: 0.046769076 | B6: 0.04788 | C6: 0.046769076 | D6: 0.04788 | F6: =IF(C6<>"",A6-C6,"") -> 2.7755576e-17 | G6: =B6-D6 -> 0 | K6: 5 | L6: 0.04788 | M6: =D6 -> 0.04788 | O6: =MAX(ABS(L6-M6)) -> 0
A7: 0.047064867 | B7: 0.04819 | C7: 0.047064867 | D7: 0.04819 | F7: =IF(C7<>"",A7-C7,"") -> 9.0205621e-17 | G7: =B7-D7 -> 0 | K7: 6 | L7: 0.04819 | M7: =D7 -> 0.04819 | O7: =MAX(ABS(L7-M7)) -> 0
A8: 0.047465478 | B8: 0.04861 | C8: 0.047465478 | D8: 0.04861 | F8: =IF(C8<>"",A8-C8,"") -> 4.1633363e-17 | G8: =B8-D8 -> 0 | K8: 7 | L8: 0.04861 | M8: =D8 -> 0.04861 | O8: =MAX(ABS(L8-M8)) -> 0
A9: 0.04791359 | B9: 0.04908 | C9: 0.04791359 | D9: 0.04908 | F9: =IF(C9<>"",A9-C9,"") -> 9.0205621e-17 | G9: =B9-D9 -> 0 | K9: 8 | L9: 0.04908 | M9: =D9 -> 0.04908 | O9: =MAX(ABS(L9-M9)) -> 0
A10: 0.048399612 | B10: 0.04959 | C10: 0.048399612 | D10: 0.04959 | F10: =IF(C10<>"",A10-C10,"") -> 6.9388939e-18 | G10: =B10-D10 -> 0 | K10: 9 | L10: 0.04959 | M10: =D10 -> 0.04959 | O10: =MAX(ABS(L10-M10)) -> 0
A11: 0.048904443 | B11: 0.05012 | C11: 0.048904443 | D11: 0.05012 | F11: =IF(C11<>"",A11-C11,"") -> 2.7755576e-17 | G11: =B11-D11 -> 0 | K11: 10 | L11: 0.05012 | M11: =D11 -> 0.05012 | O11: =MAX(ABS(L11-M11)) -> 0
A12: 0.049351911 | B12: 0.05059 | C12: 0.049351911 | D12: 0.05059 | F12: =IF(C12<>"",A12-C12,"") -> 5.5511151e-17 | G12: =B12-D12 -> 0 | K12: 11 | L12: 0.05059 | M12: =D12 -> 0.05059 | O12: =MAX(ABS(L12-M12)) -> 0
A13: 0.049808693 | B13: 0.05107 | C13: 0.049808693 | D13: 0.05107 | F13: =IF(C13<>"",A13-C13,"") -> 0 | G13: =B13-D13 -> 0 | K13: 12 | L13: 0.05107 | M13: =D13 -> 0.05107 | O13: =MAX(ABS(L13-M13)) -> 0
... A51: 0.046186778 | B51: 0.04727 | C51: 0.046186778 | D51: 0.04727 | F51: =IF(C51<>"",A51-C51,"") -> 4.8572257e-17 | G51: =B51-D51 -> 0 | K51: 50 | L51: 0.04727 | M51: =D51 -> 0.04727 | O51: =MAX(ABS(L51-M51)) -> 0
A52: #N/A | B52: 0.047 | D52: 0.047 | F52: =IF(C52<>"",A52-C52,"") | G52: =B52-D52 -> 0 | K52: 51 | L52: 0.04697 | M52: =D52 -> 0.047 | O52: =MAX(ABS(L52-M52)) -> 3e-05
A53: #N/A | B53: 0.04673 | D53: 0.04673 | F53: =IF(C53<>"",A53-C53,"") | G53: =B53-D53 -> 0 | K53: 52 | L53: 0.04668 | M53: =D53 -> 0.04673 | O53: =MAX(ABS(L53-M53)) -> 5e-05
A54: #N/A | B54: 0.04648 | D54: 0.04648 | F54: =IF(C54<>"",A54-C54,"") | G54: =B54-D54 -> 0 | K54: 53 | L54: 0.0464 | M54: =D54 -> 0.04648 | O54: =MAX(ABS(L54-M54)) -> 8e-05
A55: #N/A | B55: 0.04623 | D55: 0.04623 | F55: =IF(C55<>"",A55-C55,"") | G55: =B55-D55 -> 0 | K55: 54 | L55: 0.04613 | M55: =D55 -> 0.04623 | O55: =MAX(ABS(L55-M55)) -> 0.0001
A56: #N/A | B56: 0.046 | D56: 0.046 | F56: =IF(C56<>"",A56-C56,"") | G56: =B56-D56 -> 0 | K56: 55 | L56: 0.04587 | M56: =D56 -> 0.046 | O56: =MAX(ABS(L56-M56)) -> 0.00013
A57: #N/A | B57: 0.04577 | D57: 0.04577 | F57: =IF(C57<>"",A57-C57,"") | G57: =B57-D57 -> 0 | K57: 56 | L57: 0.04563 | M57: =D57 -> 0.04577 | O57: =MAX(ABS(L57-M57)) -> 0.00014
A58: #N/A | B58: 0.04555 | D58: 0.04555 | F58: =IF(C58<>"",A58-C58,"") | G58: =B58-D58 -> 0 | K58: 57 | L58: 0.04539 | M58: =D58 -> 0.04555 | O58: =MAX(ABS(L58-M58)) -> 0.00016
A59: #N/A | B59: 0.04533 | D59: 0.04533 | F59: =IF(C59<>"",A59-C59,"") | G59: =B59-D59 -> 0 | K59: 58 | L59: 0.04516 | M59: =D59 -> 0.04533 | O59: =MAX(ABS(L59-M59)) -> 0.00017
A60: #N/A | B60: 0.04513 | D60: 0.04513 | F60: =IF(C60<>"",A60-C60,"") | G60: =B60-D60 -> 0 | K60: 59 | L60: 0.04494 | M60: =D60 -> 0.04513 | O60: =MAX(ABS(L60-M60)) -> 0.00019
A61: #N/A | B61: 0.04493 | D61: 0.04493 | F61: =IF(C61<>"",A61-C61,"") | G61: =B61-D61 -> 0 | K61: 60 | L61: 0.04473 | M61: =D61 -> 0.04493 | O61: =MAX(ABS(L61-M61)) -> 0.0002
A62: #N/A | B62: 0.04473 | D62: 0.04473 | F62: =IF(C62<>"",A62-C62,"") | G62: =B62-D62 -> 0 | K62: 61 | L62: 0.04453 | M62: =D62 -> 0.04473 | O62: =MAX(ABS(L62-M62)) -> 0.0002
A63: #N/A | B63: 0.04454 | D63: 0.04454 | F63: =IF(C63<>"",A63-C63,"") | G63: =B63-D63 -> 0 | K63: 62 | L63: 0.04433 | M63: =D63 -> 0.04454 | O63: =MAX(ABS(L63-M63)) -> 0.00021
... A151: #N/A | B151: 0.03776 | D151: 0.03776 | F151: =IF(C151<>"",A151-C151,"") | G151: =B151-D151 -> 0 | K151: 150 | L151: 0.03761 | M151: =D151 -> 0.03776 | O151: =MAX(ABS(L151-M151)) -> 0.00015

Sheet Australia
A1: Bootstrapped Zero Rate CC | B1: Extrapolated Zero Rate AC / Basic RFR | C1: Bootstrapped Zero Rate CC | D1: Basic RFR | F1: =SUM(F2:F151) -> 1.2906343e-15 | G1: =SUM(G2:G151) -> 0 | K1: Maturity | L1: Smith-Wilson | M1: Constant forward | O1: =MAX(O2:O151) -> 0.00043 | P1: =MAX(O2:O51) -> 0.00043
A2: 0.049941882 | B2: 0.05121 | C2: 0.049941882 | D2: 0.05121 | F2: =IF(C2<>"",A2-C2,"") -> 2.0816682e-17 | G2: =B2-D2 -> 0 | K2: 1 | L2: 0.05121 | M2: =D2 -> 0.05121 | O2: =MAX(ABS(L2-M2)) -> 0
A3: 0.049989445 | B3: 0.05126 | C3: 0.049989445 | D3: 0.05126 | F3: =IF(C3<>"",A3-C3,"") -> 9.7144515e-17 | G3: =B3-D3 -> 0 | K3: 2 | L3: 0.05126 | M3: =D3 -> 0.05126 | O3: =MAX(ABS(L3-M3)) -> 0
A4: 0.049989445 | B4: 0.05126 | C4: 0.049989445 | D4: 0.05126 | F4: =IF(C4<>"",A4-C4,"") -> 8.3266727e-17 | G4: =B4-D4 -> 0 | K4: 3 | L4: 0.05126 | M4: =D4 -> 0.05126 | O4: =MAX(ABS(L4-M4)) -> 0
A5: 0.050075053 | B5: 0.05135 | C5: 0.050075053 | D5: 0.05135 | F5: =IF(C5<>"",A5-C5,"") -> 3.469447e-17 | G5: =B5-D5 -> 0 | K5: 4 | L5: 0.05135 | M5: =D5 -> 0.05135 | O5: =MAX(ABS(L5-M5)) -> 0
A6: 0.050341341 | B6: 0.05163 | C6: 0.050341341 | D6: 0.05163 | F6: =IF(C6<>"",A6-C6,"") -> 0 | G6: =B6-D6 -> 0 | K6: 5 | L6: 0.05163 | M6: =D6 -> 0.05163 | O6: =MAX(ABS(L6-M6)) -> 0
A7: 0.050911722 | B7: 0.05223 | C7: 0.050911722 | D7: 0.05223 | F7: =IF(C7<>"",A7-C7,"") -> 2.7755576e-17 | G7: =B7-D7 -> 0 | K7: 6 | L7: 0.05223 | M7: =D7 -> 0.05223 | O7: =MAX(ABS(L7-M7)) -> 0
A8: 0.051434284 | B8: 0.05278 | C8: 0.051434284 | D8: 0.05278 | F8: =IF(C8<>"",A8-C8,"") -> 0 | G8: =B8-D8 -> 0 | K8: 7 | L8: 0.05278 | M8: =D8 -> 0.05278 | O8: =MAX(ABS(L8-M8)) -> 0
A9: 0.051928093 | B9: 0.0533 | C9: 0.051928093 | D9: 0.0533 | F9: =IF(C9<>"",A9-C9,"") -> 2.0816682e-17 | G9: =B9-D9 -> 0 | K9: 8 | L9: 0.0533 | M9: =D9 -> 0.0533 | O9: =MAX(ABS(L9-M9)) -> 0
A10: 0.052421658 | B10: 0.05382 | C10: 0.052421658 | D10: 0.05382 | F10: =IF(C10<>"",A10-C10,"") -> 2.0816682e-17 | G10: =B10-D10 -> 0 | K10: 9 | L10: 0.05382 | M10: =D10 -> 0.05382 | O10: =MAX(ABS(L10-M10)) -> 0
A11: 0.052905494 | B11: 0.05433 | C11: 0.052905494 | D11: 0.05433 | F11: =IF(C11<>"",A11-C11,"") -> 6.9388939e-17 | G11: =B11-D11 -> 0 | K11: 10 | L11: 0.05433 | M11: =D11 -> 0.05433 | O11: =MAX(ABS(L11-M11)) -> 0
A12: 0.053332214 | B12: 0.05478 | C12: 0.053332214 | D12: 0.05478 | F12: =IF(C12<>"",A12-C12,"") -> 6.9388939e-17 | G12: =B12-D12 -> 0 | K12: 11 | L12: 0.05478 | M12: =D12 -> 0.05478 | O12: =MAX(ABS(L12-M12)) -> 0
A13: 0.053682937 | B13: 0.05515 | C13: 0.053682937 | D13: 0.05515 | F13: =IF(C13<>"",A13-C13,"") -> 6.9388939e-17 | G13: =B13-D13 -> 0 | K13: 12 | L13: 0.05515 | M13: =D13 -> 0.05515 | O13: =MAX(ABS(L13-M13)) -> 0
... A31: 0.052174906 | B31: 0.05356 | C31: 0.052174906 | D31: 0.05356 | F31: =IF(C31<>"",A31-C31,"") -> 5.5511151e-17 | G31: =B31-D31 -> 0 | K31: 30 | L31: 0.05356 | M31: =D31 -> 0.05356 | O31: =MAX(ABS(L31-M31)) -> 0
A32: #N/A | B32: 0.05331 | D32: 0.05331 | F32: =IF(C32<>"",A32-C32,"") | G32: =B32-D32 -> 0 | K32: 31 | L32: 0.05324 | M32: =D32 -> 0.05331 | O32: =MAX(ABS(L32-M32)) -> 7e-05
A33: #N/A | B33: 0.05303 | D33: 0.05303 | F33: =IF(C33<>"",A33-C33,"") | G33: =B33-D33 -> 0 | K33: 32 | L33: 0.0529 | M33: =D33 -> 0.05303 | O33: =MAX(ABS(L33-M33)) -> 0.00013
A34: #N/A | B34: 0.05273 | D34: 0.05273 | F34: =IF(C34<>"",A34-C34,"") | G34: =B34-D34 -> 0 | K34: 33 | L34: 0.05255 | M34: =D34 -> 0.05273 | O34: =MAX(ABS(L34-M34)) -> 0.00018
A35: #N/A | B35: 0.05242 | D35: 0.05242 | F35: =IF(C35<>"",A35-C35,"") | G35: =B35-D35 -> 0 | K35: 34 | L35: 0.05219 | M35: =D35 -> 0.05242 | O35: =MAX(ABS(L35-M35)) -> 0.00023
A36: #N/A | B36: 0.0521 | D36: 0.0521 | F36: =IF(C36<>"",A36-C36,"") | G36: =B36-D36 -> 0 | K36: 35 | L36: 0.05184 | M36: =D36 -> 0.0521 | O36: =MAX(ABS(L36-M36)) -> 0.00026
A37: #N/A | B37: 0.05177 | D37: 0.05177 | F37: =IF(C37<>"",A37-C37,"") | G37: =B37-D37 -> 0 | K37: 36 | L37: 0.05148 | M37: =D37 -> 0.05177 | O37: =MAX(ABS(L37-M37)) -> 0.00029
A38: #N/A | B38: 0.05144 | D38: 0.05144 | F38: =IF(C38<>"",A38-C38,"") | G38: =B38-D38 -> 0 | K38: 37 | L38: 0.05112 | M38: =D38 -> 0.05144 | O38: =MAX(ABS(L38-M38)) -> 0.00032
A39: #N/A | B39: 0.05111 | D39: 0.05111 | F39: =IF(C39<>"",A39-C39,"") | G39: =B39-D39 -> 0 | K39: 38 | L39: 0.05077 | M39: =D39 -> 0.05111 | O39: =MAX(ABS(L39-M39)) -> 0.00034
A40: #N/A | B40: 0.05078 | D40: 0.05078 | F40: =IF(C40<>"",A40-C40,"") | G40: =B40-D40 -> 0 | K40: 39 | L40: 0.05042 | M40: =D40 -> 0.05078 | O40: =MAX(ABS(L40-M40)) -> 0.00036
A41: #N/A | B41: 0.05045 | D41: 0.05045 | F41: =IF(C41<>"",A41-C41,"") | G41: =B41-D41 -> 0 | K41: 40 | L41: 0.05008 | M41: =D41 -> 0.05045 | O41: =MAX(ABS(L41-M41)) -> 0.00037
A42: #N/A | B42: 0.05013 | D42: 0.05013 | F42: =IF(C42<>"",A42-C42,"") | G42: =B42-D42 -> 0 | K42: 41 | L42: 0.04974 | M42: =D42 -> 0.05013 | O42: =MAX(ABS(L42-M42)) -> 0.00039
A43: #N/A | B43: 0.04981 | D43: 0.04981 | F43: =IF(C43<>"",A43-C43,"") | G43: =B43-D43 -> 0 | K43: 42 | L43: 0.04941 | M43: =D43 -> 0.04981 | O43: =MAX(ABS(L43-M43)) -> 0.0004
... A151: #N/A | B151: 0.0379 | D151: 0.0379 | F151: =IF(C151<>"",A151-C151,"") | G151: =B151-D151 -> 0 | K151: 150 | L151: 0.03773 | M151: =D151 -> 0.0379 | O151: =MAX(ABS(L151-M151)) -> 0.00017

Sheet US
A1: Bootstrapped Zero Rate CC | B1: Extrapolated Zero Rate AC / Basic RFR | C1: Bootstrapped Zero Rate CC | D1: Basic RFR | F1: =SUM(F2:F151) -> 1.4988011e-15 | G1: =SUM(G2:G151) -> 0 | K1: Maturity | L1: Smith-Wilson | M1: Constant forward | O1: =MAX(O2:O151) -> 0.00034 | P1: =MAX(O2:O51) -> 0.00034
A2: 0.044447415 | B2: 0.04545 | C2: 0.044447415 | D2: 0.04545 | F2: =IF(C2<>"",A2-C2,"") -> 4.8572257e-17 | G2: =B2-D2 -> 0 | K2: 1 | L2: 0.04545 | M2: =D2 -> 0.04545 | O2: =MAX(ABS(L2-M2)) -> 0
A3: 0.046444558 | B3: 0.04754 | C3: 0.046444558 | D3: 0.04754 | F3: =IF(C3<>"",A3-C3,"") -> 4.1633363e-17 | G3: =B3-D3 -> 0 | K3: 2 | L3: 0.04754 | M3: =D3 -> 0.04754 | O3: =MAX(ABS(L3-M3)) -> 0
A4: 0.046883586 | B4: 0.048 | C4: 0.046883586 | D4: 0.048 | F4: =IF(C4<>"",A4-C4,"") -> 6.2450045e-17 | G4: =B4-D4 -> 0 | K4: 3 | L4: 0.048 | M4: =D4 -> 0.048 | O4: =MAX(ABS(L4-M4)) -> 0
A5: 0.04696946 | B5: 0.04809 | C5: 0.04696946 | D5: 0.04809 | F5: =IF(C5<>"",A5-C5,"") -> 6.9388939e-17 | G5: =B5-D5 -> 0 | K5: 4 | L5: 0.04809 | M5: =D5 -> 0.04809 | O5: =MAX(ABS(L5-M5)) -> 0
A6: 0.047064867 | B6: 0.04819 | C6: 0.047064867 | D6: 0.04819 | F6: =IF(C6<>"",A6-C6,"") -> 6.9388939e-18 | G6: =B6-D6 -> 0 | K6: 5 | L6: 0.04819 | M6: =D6 -> 0.04819 | O6: =MAX(ABS(L6-M6)) -> 0
A7: 0.0472175 | B7: 0.04835 | C7: 0.0472175 | D7: 0.04835 | F7: =IF(C7<>"",A7-C7,"") -> 6.9388939e-17 | G7: =B7-D7 -> 0 | K7: 6 | L7: 0.04835 | M7: =D7 -> 0.04835 | O7: =MAX(ABS(L7-M7)) -> 0
A8: 0.04739872 | B8: 0.04854 | C8: 0.04739872 | D8: 0.04854 | F8: =IF(C8<>"",A8-C8,"") -> 4.8572257e-17 | G8: =B8-D8 -> 0 | K8: 7 | L8: 0.04854 | M8: =D8 -> 0.04854 | O8: =MAX(ABS(L8-M8)) -> 0
A9: 0.047598979 | B9: 0.04875 | C9: 0.047598979 | D9: 0.04875 | F9: =IF(C9<>"",A9-C9,"") -> 5.5511151e-17 | G9: =B9-D9 -> 0 | K9: 8 | L9: 0.04875 | M9: =D9 -> 0.04875 | O9: =MAX(ABS(L9-M9)) -> 0
A10: 0.047827796 | B10: 0.04899 | C10: 0.047827796 | D10: 0.04899 | F10: =IF(C10<>"",A10-C10,"") -> 4.1633363e-17 | G10: =B10-D10 -> 0 | K10: 9 | L10: 0.04899 | M10: =D10 -> 0.04899 | O10: =MAX(ABS(L10-M10)) -> 0
A11: 0.048094684 | B11: 0.04927 | C11: 0.048094684 | D11: 0.04927 | F11: =IF(C11<>"",A11-C11,"") -> 1.3877788e-17 | G11: =B11-D11 -> 0 | K11: 10 | L11: 0.04927 | M11: =D11 -> 0.04927 | O11: =MAX(ABS(L11-M11)) -> 0
A12: 0.048396109 | B12: 0.04959 | C12: 0.048396109 | D12: 0.04959 | F12: =IF(C12<>"",A12-C12,"") -> 2.0816682e-17 | G12: =B12-D12 -> 0 | K12: 11 | L12: 0.04956 | M12: =D12 -> 0.04959 | O12: =MAX(ABS(L12-M12)) -> 3e-05
A13: 0.048647297 | B13: 0.04985 | C13: 0.048647297 | D13: 0.04985 | F13: =IF(C13<>"",A13-C13,"") -> 6.9388939e-17 | G13: =B13-D13 -> 0 | K13: 12 | L13: 0.04985 | M13: =D13 -> 0.04985 | O13: =MAX(ABS(L13-M13)) -> 0
... A31: 0.048228101 | B31: 0.04941 | C31: 0.048228101 | D31: 0.04941 | F31: =IF(C31<>"",A31-C31,"") -> 6.9388939e-18 | G31: =B31-D31 -> 0 | K31: 30 | L31: 0.04941 | M31: =D31 -> 0.04941 | O31: =MAX(ABS(L31-M31)) -> 0
A32: #N/A | B32: 0.04921 | D32: 0.04921 | F32: =IF(C32<>"",A32-C32,"") | G32: =B32-D32 -> 0 | K32: 31 | L32: 0.04914 | M32: =D32 -> 0.04921 | O32: =MAX(ABS(L32-M32)) -> 7e-05
A33: #N/A | B33: 0.04899 | D33: 0.04899 | F33: =IF(C33<>"",A33-C33,"") | G33: =B33-D33 -> 0 | K33: 32 | L33: 0.04887 | M33: =D33 -> 0.04899 | O33: =MAX(ABS(L33-M33)) -> 0.00012
A34: #N/A | B34: 0.04875 | D34: 0.04875 | F34: =IF(C34<>"",A34-C34,"") | G34: =B34-D34 -> 0 | K34: 33 | L34: 0.04859 | M34: =D34 -> 0.04875 | O34: =MAX(ABS(L34-M34)) -> 0.00016
A35: #N/A | B35: 0.04851 | D35: 0.04851 | F35: =IF(C35<>"",A35-C35,"") | G35: =B35-D35 -> 0 | K35: 34 | L35: 0.0483 | M35: =D35 -> 0.04851 | O35: =MAX(ABS(L35-M35)) -> 0.00021
A36: #N/A | B36: 0.04825 | D36: 0.04825 | F36: =IF(C36<>"",A36-C36,"") | G36: =B36-D36 -> 0 | K36: 35 | L36: 0.04801 | M36: =D36 -> 0.04825 | O36: =MAX(ABS(L36-M36)) -> 0.00024
A37: #N/A | B37: 0.04799 | D37: 0.04799 | F37: =IF(C37<>"",A37-C37,"") | G37: =B37-D37 -> 0 | K37: 36 | L37: 0.04773 | M37: =D37 -> 0.04799 | O37: =MAX(ABS(L37-M37)) -> 0.00026
A38: #N/A | B38: 0.04773 | D38: 0.04773 | F38: =IF(C38<>"",A38-C38,"") | G38: =B38-D38 -> 0 | K38: 37 | L38: 0.04745 | M38: =D38 -> 0.04773 | O38: =MAX(ABS(L38-M38)) -> 0.00028
A39: #N/A | B39: 0.04746 | D39: 0.04746 | F39: =IF(C39<>"",A39-C39,"") | G39: =B39-D39 -> 0 | K39: 38 | L39: 0.04717 | M39: =D39 -> 0.04746 | O39: =MAX(ABS(L39-M39)) -> 0.00029
A40: #N/A | B40: 0.0472 | D40: 0.0472 | F40: =IF(C40<>"",A40-C40,"") | G40: =B40-D40 -> 0 | K40: 39 | L40: 0.04689 | M40: =D40 -> 0.0472 | O40: =MAX(ABS(L40-M40)) -> 0.00031
A41: #N/A | B41: 0.04694 | D41: 0.04694 | F41: =IF(C41<>"",A41-C41,"") | G41: =B41-D41 -> 0 | K41: 40 | L41: 0.04662 | M41: =D41 -> 0.04694 | O41: =MAX(ABS(L41-M41)) -> 0.00032
A42: #N/A | B42: 0.04668 | D42: 0.04668 | F42: =IF(C42<>"",A42-C42,"") | G42: =B42-D42 -> 0 | K42: 41 | L42: 0.04635 | M42: =D42 -> 0.04668 | O42: =MAX(ABS(L42-M42)) -> 0.00033
A43: #N/A | B43: 0.04642 | D43: 0.04642 | F43: =IF(C43<>"",A43-C43,"") | G43: =B43-D43 -> 0 | K43: 42 | L43: 0.04609 | M43: =D43 -> 0.04642 | O43: =MAX(ABS(L43-M43)) -> 0.00033
... A151: #N/A | B151: 0.03692 | D151: 0.03692 | F151: =IF(C151<>"",A151-C151,"") | G151: =B151-D151 -> 0 | K151: 150 | L151: 0.03679 | M151: =D151 -> 0.03692 | O151: =MAX(ABS(L151-M151)) -> 0.00013

Sheet Taiwan
A1: Bootstrapped Zero Rate CC | B1: Extrapolated Zero Rate AC / Basic RFR | C1: Bootstrapped Zero Rate CC | D1: Basic RFR | F1: =SUM(F2:F151) -> 4.4929338e-16 | G1: =SUM(G2:G151) -> 0 | K1: Maturity | L1: Smith-Wilson | M1: Constant forward | O1: =MAX(O2:O151) -> 0.00013 | P1: =MAX(O2:O51) -> 0.00013
A2: 0.012452149 | B2: 0.01253 | C2: 0.012452149 | D2: 0.01253 | F2: =IF(C2<>"",A2-C2,"") -> 8.6736174e-18 | G2: =B2-D2 -> 0 | K2: 1 | L2: 0.01253 | M2: =D2 -> 0.01253 | O2: =MAX(ABS(L2-M2)) -> 0
A3: 0.013064289 | B3: 0.01315 | C3: 0.013064289 | D3: 0.01315 | F3: =IF(C3<>"",A3-C3,"") -> 7.979728e-17 | G3: =B3-D3 -> 0 | K3: 2 | L3: 0.01315 | M3: =D3 -> 0.01315 | O3: =MAX(ABS(L3-M3)) -> 0
